Workbook

Sheet Instruções
D2: ARQ. ANEXADO II - QUANTITATIVO PADRÃO DE ESTRUTURA DE CONCRETO (AÇO E CONCRETO) OPE-PR-005 - V.0
D3: REVISÃO: 00
D4: ELABORAÇÃO: 30/06/2025
B6: OBRA:
B7: RESP. OBRA:
B8: RESP. PREENCHIMENTO:
C10: - Em cada aba, preencher apenas células em amarelo
C11: - A Armação deve ser levantada conforme resumo de aço dos projetos, nas abas AÇO
C12: - As dimensões das peças estruturais devem ser levantadas nas abas de cada pavimento do empreendimento, ou das peças de fundação/contenção
B14: 1 | C14: Aço Blocos e Aço Estrutura | D14: Identificar a folha do projeto na coluna B, e a respectiva peça estrutural na coluna E
B15: 2 | D15: Apartir dos resumos encontrados nas folhas de armação, colocar a pesagem total de cada bitola nas colunas H a S
B16: 3 | D16: Alterar as cédulas em amarelo, caso possuir alguma bitola diferente
B17: 4 | D17: Levantar a armação da obra, descrevendo os projetos utilizados. Atentar a quantidade de repetições para uma mesma folha, por exemplo, o tipo. Levantar o aço separado por bitola, bem como as telas da cubeta. Em obras de alvenaria estrutural, levantar separado a armação da alvenaria e dos muros, se atentando as repetições das paredes e muros.
B18: 5 | C18: Concreto Blocos | D18: Alterar as cédulas em amarelo caso seja necessário realizar concreto com gelo e o traço que será utilizado convencionalmente
B19: 6 | C19: Concreto Estrutura | D19: Alterar a nomenclatura das cédulas em amarelo na coluna B conforme os pavimentos de acordo com os projetos. Alterar o nome das abas de acordo com os nomes preenchidos na coluna B.
B20: 7 | D20: Alterar as cédulas em amarelo na coluna C com a área de projeção em cada pavimento.
B21: 8 | D21: Analisar o Fck do concreto no projeto e o slump conforme tabela da concreteira, analisando a metragem de tubulação da bomba na obra. Alterar as cédulas em amarelo na coluna D.
B22: 9 | C22: Pilares | D22: Obedecer à numeração do calculista no projeto de estrutura. Caso não haja numeração do calculista, segue-se o seguinte critério: da esquerda para direita, do fundo para frente
B23: 10 | D23: A quantidade (q) refere-se ao número de vezes que ocorre o mesmo pilar, isto é, com as mesmas dimensões (b, a, l)
B24: 11 | D24: A largura do pilar (b) refere-se a menor dimensão da peça.
B25: 12 | D25: O comprimento do pilar (a) refere-se a maior dimensão do pilar.
B26: 13 | D26: A altura do pilar (l) será do piso do pavimento inferior ao piso do pavimento superior, considerando a espessura das lajes
B27: 14 | C27: Vigas | D27: Obedecer à numeração do calculista no projeto de estrutura. Caso não haja numeração do calculista, segue-se o seguinte critério: da esquerda para direita, do fundo para frente.
B28: 15 | D28: As quantidades (q) referem-se ao número de vezes que ocorre a mesma viga, isto é, com as mesmas dimensões (b, a, l).
B29: 16 | D29: A base da viga (b) considera-se a primeira cota do calculista corresponde ao fundo da viga.
B30: 17 | D30: A altura da viga (a) considera-se a segunda cota do calculista corresponde a lateral da viga.
B31: 18 | D31: O comprimento da viga (l) deve-se a distância compreendida entre duas peças estruturais, mesmo que a numeração englobe vários vãos. Nesse caso, dividiremos a viga em quantas partes forem necessárias
B32: 19 | C32: Escadas | D32: Para simplificação do levantamento das peças estruturais nas escadas, o impresso a ser utilizado foi subdividido. O impresso é destinado somente a escadas do tipo mostrado na figura abaixo não devendo ser empregado se o tipo de escada for diferente desta apresentada.
B33: 20 | C33: Escadas - DEGRAU | D33: O seu volume é calculado considerando-se que 2 peças formam um retângulo, por isso, o resultado obtido (volume parcial) deve ser dividido por 2. Para o cálculo de formas, consideramos somente os espelhos.
B34: 21 | C34: Escadas - LAJE DE APOIO | D34: O levantamento é idêntico ao de uma laje normal, tomando-se a precaução de calcular o comprimento pela hipotenusa do triângulo retângulo.
B35: 22 | C35: Escadas - Patamar | D35: O levantamento é feito adotando-se os critérios da laje normal.
B36: 23 | C36: Cortinas | D36: Levantar base, altura e comprimento das cortinas conforme projetos.
B37: 24 | C37: Lajes | D37: Se atentar as lajes intermediárias dos pavimentos (rampas, lajes dupla de piscina, teto de reservatório). Obedecer à numeração do calculista em projeto de estrutura. Caso não haja numeração do calculista, segue-se o seguinte critério: da esquerda para direita, do fundo para frente conforme figura \o lado:
B38: 25 | D38: Separar em número de vezes que ocorre a mesma laje (q), isto é, com as mesmas dimensões (l x a x b).
B39: 26 | D39: O comprimento (l) é definido como a maior dimensão.
B40: 27 | D40: A largura (a) é definida como a menor dimensão.
B41: 28 | D41: A altura (b) corresponde à espessura da laje.
B42: 29 | D42: Analisar o Fck do concreto no projeto e o slump conforme tabela da concreteira, analisando a metragem de tubulação da bomba na obra.
B43: 30 | C43: Cubetas | D43: Obedecer à numeração da laje do calculista no projeto de estrutura ou mapear o trecho considerado. Inserir largura, altura e comprimento da laje. Quantificar a quantidade de cubeta no trecho considerado e inserir o volume de vazios por cubeta conforme tabela do fornecedor.

Sheet AÇO - Blocos de fundação
B2: QUANTITATIVO DE AÇO - FUNDAÇÃO
B3: PROJETO - FOLHA | E3: PEÇA ESTRUTURAL | F3: QUANTIDADE TOTAL | G3: UNIDADE | H3: AÇO CA - 50 | Q3: AÇO CA-60 | T3: TOTAL
H4: 6,30mm | I4: 8,00mm | J4: 10,00mm | K4: 12,50mm | L4: 16,00mm | M4: 20,00mm | N4: 25,00mm | O4: 32,00mm | P4: 0 | Q4: 5,00mm | R4: 0 | S4: 0 | T4: POR FOLHA
T5: =SUM(Q5:S5) -> 0
B6: FUNDAÇÃO (BLOCOS E VIGAS BALDRAMES)
B7: Blocos e vigas baldrames para ESTACA HÉLICE
G8: kg | T8: =SUM(H8:S8) -> 0
G9: kg | T9: =SUM(H9:S9) -> 0
G10: kg | T10: =SUM(H10:S10) -> 0
G11: kg | T11: =SUM(H11:S11) -> 0
G12: kg | T12: =SUM(H12:S12) -> 0
G13: kg | T13: =SUM(H13:S13) -> 0
G14: kg | T14: =SUM(H14:S14) -> 0
G15: kg | T15: =SUM(H15:S15) -> 0
G16: kg | T16: =SUM(H16:S16) -> 0
G17: kg | T17: =SUM(H17:S17) -> 0
G18: kg | T18: =SUM(H18:S18) -> 0
G19: kg | T19: =SUM(H19:S19) -> 0
... G27: kg | T27: =SUM(H27:S27) -> 0
B28: Resumo | T28: =SUM(T8:T27) -> 0
B29: Ferro 6,3 mm - CA-50 (cortado e dobrado) | E29: =$B$7 -> Blocos e vigas baldrames para ESTACA HÉLICE | F29: =H29 -> 0 | G29: kg | H29: =SUM(H8:H27) -> 0 | T29: =SUM(H29:S40) -> 0
B30: Ferro 8,0 mm - CA-50 (cortado e dobrado) | E30: =$B$7 -> Blocos e vigas baldrames para ESTACA HÉLICE | F30: =I30 -> 0 | G30: kg | I30: =SUM(I8:I27) -> 0 | T30: =T28=T29 -> TRUE
B31: Ferro 10,0 mm - CA-50 (cortado e dobrado) | E31: =$B$7 -> Blocos e vigas baldrames para ESTACA HÉLICE | F31: =J31 -> 0 | G31: kg | J31: =SUM(J8:J27) -> 0
B32: Ferro 12,5 mm - CA-50 (cortado e dobrado) | E32: =$B$7 -> Blocos e vigas baldrames para ESTACA HÉLICE | F32: =K32 -> 0 | G32: kg | K32: =SUM(K8:K27) -> 0
B33: Ferro 16,0 mm - CA-50 (cortado e dobrado) | E33: =$B$7 -> Blocos e vigas baldrames para ESTACA HÉLICE | F33: =L33 -> 0 | G33: kg | L33: =SUM(L8:L27) -> 0
B34: Ferro 20,0 mm - CA-50 (cortado e dobrado) | E34: =$B$7 -> Blocos e vigas baldrames para ESTACA HÉLICE | F34: =M34 -> 0 | G34: kg | M34: =SUM(M8:M27) -> 0
B35: Ferro 25,0 mm - CA-50 (cortado e dobrado) | E35: =$B$7 -> Blocos e vigas baldrames para ESTACA HÉLICE | F35: =N35 -> 0 | G35: kg | N35: =SUM(N8:N27) -> 0
B36: Ferro 32,0 mm - CA-50 (cortado e dobrado) | E36: =$B$7 -> Blocos e vigas baldrames para ESTACA HÉLICE | F36: =O36 -> 0 | G36: kg | O36: =SUM(O8:O27) -> 0
B37: Ferro ... - CA-50 (cortado e dobrado) | E37: =$B$7 -> Blocos e vigas baldrames para ESTACA HÉLICE | F37: =P37 -> 0 | G37: kg | P37: =SUM(P8:P27) -> 0
B38: Ferro 5,0 mm - CA-60 (cortado e dobrado) | E38: =$B$7 -> Blocos e vigas baldrames para ESTACA HÉLICE | F38: =Q38 -> 0 | G38: kg | Q38: =SUM(Q8:Q27) -> 0
B39: Ferro ... - CA-60 (cortado e dobrado) | E39: =$B$7 -> Blocos e vigas baldrames para ESTACA HÉLICE | F39: =R39 -> 0 | G39: kg | R39: =SUM(R8:R27) -> 0
B40: Ferro ... - CA-60 (cortado e dobrado) | E40: =$B$7 -> Blocos e vigas baldrames para ESTACA HÉLICE | F40: =S40 -> 0 | G40: kg | S40: =SUM(S8:S27) -> 0
B41: Blocos e vigas baldrames para PERFIL DE FUNDAÇÃO
G42: kg | T42: =SUM(H42:S42) -> 0
G43: kg | T43: =SUM(H43:S43) -> 0
G44: kg | T44: =SUM(H44:S44) -> 0
G45: kg | T45: =SUM(H45:S45) -> 0
G46: kg | T46: =SUM(H46:S46) -> 0
G47: kg | T47: =SUM(H47:S47) -> 0
G48: kg | T48: =SUM(H48:S48) -> 0
...

Sheet AÇO - Estrutura
B2: QUANTITATIVO ARMAÇÃO ESTRUTURA
B3: PROJETO - FOLHA | E3: PEÇA ESTRUTURAL | F3: QUANTIDADE TOTAL | G3: UNIDADE | H3: AÇO CA - 50 | Q3: AÇO CA-60 | T3: TELAS | W3: TOTAL
H4: 6,30mm | I4: 8,00mm | J4: 10,00mm | K4: 12,50mm | L4: 16,00mm | M4: 20,00mm | N4: 25,00mm | O4: 32,00mm | P4: 0 | Q4: 5,00mm | R4: 4,20mm | S4: 0 | T4: Tela Q75 | U4: Tela Q92 | V4: 0 | W4: POR FOLHA
W5: =SUM(Q5:S5) -> 0
B6: ESTRUTURA
G7: kg | W7: =SUM(H7:V7) -> 0
G8: kg | W8: =SUM(H8:V8) -> 0
G9: kg | W9: =SUM(H9:V9) -> 0
G10: kg | W10: =SUM(H10:V10) -> 0
G11: kg | W11: =SUM(H11:V11) -> 0
G12: kg | W12: =SUM(H12:V12) -> 0
G13: kg | W13: =SUM(H13:V13) -> 0
G14: kg | W14: =SUM(H14:V14) -> 0
G15: kg | W15: =SUM(H15:V15) -> 0
G16: kg | W16: =SUM(H16:V16) -> 0
G17: kg | W17: =SUM(H17:V17) -> 0
G18: kg | W18: =SUM(H18:V18) -> 0
... G113: kg | W113: =SUM(H113:V113) -> 0
B114: Resumo | W114: =SUM(W7:W113) -> 0
B115: Ferro 6,3 mm - CA-50 (cortado e dobrado) | E115: Estrutura | F115: =H115 -> 0 | G115: kg | H115: =SUM(H7:H113) -> 0 | W115: =SUM(H115:V129) -> 0
B116: Ferro 8,0 mm - CA-50 (cortado e dobrado) | E116: Estrutura | F116: =I116 -> 0 | G116: kg | I116: =SUM(I7:I113) -> 0 | W116: =W114=W115 -> TRUE
B117: Ferro 10,0 mm - CA-50 (cortado e dobrado) | E117: Estrutura | F117: =J117 -> 0 | G117: kg | J117: =SUM(J7:J113) -> 0
B118: Ferro 12,5 mm - CA-50 (cortado e dobrado) | E118: Estrutura | F118: =K118 -> 0 | G118: kg | K118: =SUM(K7:K113) -> 0
B119: Ferro 16,0 mm - CA-50 (cortado e dobrado) | E119: Estrutura | F119: =L119 -> 0 | G119: kg | L119: =SUM(L7:L113) -> 0
B120: Ferro 20,0 mm - CA-50 (cortado e dobrado) | E120: Estrutura | F120: =M120 -> 0 | G120: kg | M120: =SUM(M7:M113) -> 0
B121: Ferro 25,0 mm - CA-50 (cortado e dobrado) | E121: Estrutura | F121: =N121 -> 0 | G121: kg | N121: =SUM(N7:N113) -> 0
B122: Ferro 32,0 mm - CA-50 (cortado e dobrado) | E122: Estrutura | F122: =O122 -> 0 | G122: kg | O122: =SUM(O7:O113) -> 0
B123: Ferro ... - CA-50 (cortado e dobrado) | E123: Estrutura | F123: =P123 -> 0 | G123: kg | P123: =SUM(P7:P113) -> 0
B124: Ferro 5,0 mm - CA-60 (cortado e dobrado) | E124: Estrutura | F124: =Q124 -> 0 | G124: kg | Q124: =SUM(Q7:Q113) -> 0
B125: Ferro ... - CA-60 (cortado e dobrado) | E125: Estrutura | F125: =R125 -> 0 | G125: kg | R125: =SUM(R7:R113) -> 0
B126: Ferro ... - CA-60 (cortado e dobrado) | E126: Estrutura | F126: =S126 -> 0 | G126: kg | S126: =SUM(S7:S113) -> 0
B127: Tela Q75 | E127: Estrutura | F127: =T127 -> 0 | G127: kg | T127: =SUM(T7:T113) -> 0
B128: Tela Q92 | E128: Estrutura | F128: =U128 -> 0 | G128: kg | U128: =SUM(U7:U113) -> 0
B129: Tela ... | E129: Estrutura | F129: =V129 -> 0 | G129: kg | V129: =SUM(V7:V113) -> 0
B130: CORTINAS MOLDADAS IN-LOCO
G131: kg | W131: =SUM(H131:V131) -> 0
G132: kg | W132: =SUM(H132:V132) -> 0
G133: kg | W133: =SUM(H133:V133) -> 0
G134: kg | W134: =SUM(H134:V134) -> 0
G135: kg | W135: =SUM(H135:V135) -> 0
...

Sheet Resumo - Volume Fundação
B2: RESUMO DE FUNDAÇÃO - CONCRETO
B3: ITEM | D3: DETALHAMENTO | E3: BLOCOS DE FUNDAÇÃO | F3: VIGAS BALDRAMES | G3: UNIDADE | H3: TOTAL
B4: Blocos e vigas baldrames para ESTACA HÉLICE
B5: Volume de escavação | D5: Volume total a escavar | E5: ='Blocos de fundação'!N68+'Blocos de fundação'!N144 -> 0 | F5: ='Vigas baldrames'!M55 -> 0 | G5: m3 | H5: =E5+F5 -> 0
B6: Área de lastro | D6: Concreto Fck - 13,5 Mpa / Slump 6 ± 1 - Brita 1 e 2 | E6: ='Blocos de fundação'!K68+'Blocos de fundação'!K144 -> 0 | F6: ='Vigas baldrames'!G55 -> 0 | G6: m2 | H6: =E6+F6 -> 0
B7: Área de forma | D7: Material | E7: ='Blocos de fundação'!L68+'Blocos de fundação'!L144 -> 0 | F7: ='Vigas baldrames'!H55 -> 0 | G7: m2 | H7: =E7+F7 -> 0
B8: Volume de concreto tipo 01 | D8: Concreto Fck - 30,0 MPa / Slump 9 ± 1 - Brita 1 | E8: ='Blocos de fundação'!K69+'Blocos de fundação'!K145 -> 0 | F8: ='Vigas baldrames'!I55 -> 0 | G8: m3 | H8: =E8+F8 -> 0
B9: Volume de concreto tipo 02 | D9: Concreto ... com gelo | E9: ='Blocos de fundação'!O69+'Blocos de fundação'!O145 -> 0 | G9: m3 | H9: =E9+F9 -> 0
B10: Blocos e vigas baldrames para PERFIL DE FUNDAÇÃO
B11: Volume de escavação | D11: Volume total a escavar | E11: ='Blocos de fundação'!N212+'Blocos de fundação'!N280 -> 0 | F11: ='Vigas baldrames'!M109 -> 0 | G11: m3 | H11: =E11+F11 -> 0
B12: Área de lastro | D12: Concreto Fck - 13,5 Mpa / Slump 6 ± 1 - Brita 1 e 2 | E12: ='Blocos de fundação'!K212+'Blocos de fundação'!K280 -> 0 | F12: ='Vigas baldrames'!G109 -> 0 | G12: m2 | H12: =E12+F12 -> 0
B13: Área de forma | D13: Material | E13: ='Blocos de fundação'!L212+'Blocos de fundação'!L280 -> 0 | F13: ='Vigas baldrames'!H109 -> 0 | G13: m2 | H13: =E13+F13 -> 0
B14: Volume de concreto tipo 01 | D14: Concreto Fck - 30,0 MPa / Slump 9 ± 1 - Brita 1 | E14: ='Blocos de fundação'!K213+'Blocos de fundação'!K281 -> 0 | F14: ='Vigas baldrames'!I109 -> 0 | G14: m3 | H14: =E14+F14 -> 0
B15: Volume de concreto tipo 02 | D15: Concreto ... com gelo | E15: ='Blocos de fundação'!O213+'Blocos de fundação'!O281 -> 0 | G15: m3 | H15: =E15+F15 -> 0
B16: Blocos e vigas baldrames para ESTACA STRAUSS
B17: Volume de escavação | D17: Volume total a escavar | E17: ='Blocos de fundação'!N348+'Blocos de fundação'!N416 -> 0 | F17: ='Vigas baldrames'!M163 -> 0 | G17: m3 | H17: =E17+F17 -> 0
B18: Área de lastro | D18: Concreto Fck - 13,5 Mpa / Slump 6 ± 1 - Brita 1 e 2 | E18: ='Blocos de fundação'!K348+'Blocos de fundação'!K416 -> 0 | F18: ='Vigas baldrames'!G163 -> 0 | G18: m2 | H18: =E18+F18 -> 0
B19: Área de forma | D19: Material | E19: ='Blocos de fundação'!L348+'Blocos de fundação'!L416 -> 0 | F19: ='Vigas baldrames'!H163 -> 0 | G19: m2 | H19: =E19+F19 -> 0
B20: Volume de concreto tipo 01 | D20: Concreto Fck - 30,0 MPa / Slump 9 ± 1 - Brita 1 | E20: ='Blocos de fundação'!K349+'Blocos de fundação'!K417 -> 0 | F20: ='Vigas baldrames'!I163 -> 0 | G20: m3 | H20: =E20+F20 -> 0
B21: Volume de concreto tipo 02 | D21: Concreto ... com gelo | E21: ='Blocos de fundação'!O349+'Blocos de fundação'!O417 -> 0 | G21: m3 | H21: =E21+F21 -> 0
B22: Blocos e vigas baldrames para ESTACA BARRETE
B23: Volume de escavação | D23: Volume total a escavar | E23: ='Blocos de fundação'!N484+'Blocos de fundação'!N552 -> 0 | F23: ='Vigas baldrames'!M217 -> 0 | G23: m3 | H23: =E23+F23 -> 0
B24: Área de lastro | D24: Concreto Fck - 13,5 Mpa / Slump 6 ± 1 - Brita 1 e 2 | E24: ='Blocos de fundação'!K484+'Blocos de fundação'!K552 -> 0 | F24: ='Vigas baldrames'!G217 -> 0 | G24: m2 | H24: =E24+F24 -> 0
B25: Área de forma | D25: Material | E25: ='Blocos de fundação'!L484+'Blocos de fundação'!L552 -> 0 | F25: ='Vigas baldrames'!H217 -> 0 | G25: m2 | H25: =E25+F25 -> 0
B26: Volume de concreto tipo 01 | D26: Concreto Fck - 30,0 MPa / Slump 9 ± 1 - Brita 1 | E26: ='Blocos de fundação'!K485+'Blocos de fundação'!K553 -> 0 | F26: ='Vigas baldrames'!I217 -> 0 | G26: m3 | H26: =E26+F26 -> 0
B27: Volume de concreto tipo 02 | D27: Concreto ... com gelo | E27: ='Blocos de fundação'!O485+'Blocos de fundação'!O553 -> 0 | G27: m3 | H27: =E27+F27 -> 0
B28: Blocos e vigas baldrames para ESTACA ESCAVADA
B29: Volume de escavação | D29: Volume total a escavar | E29: ='Blocos de fundação'!N620+'Blocos de fundação'!N688 -> 0 | F29: ='Vigas baldrames'!M271 -> 0 | G29: m3 | H29: =E29+F29 -> 0
B30: Área de lastro | D30: Concreto Fck - 13,5 Mpa / Slump 6 ± 1 - Brita 1 e 2 | E30: ='Blocos de fundação'!K620+'Blocos de fundação'!K688 -> 0 | F30: ='Vigas baldrames'!G271 -> 0 | G30: m2 | H30: =E30+F30 -> 0
B31: Área de forma | D31: Material | E31: ='Blocos de fundação'!L620+'Blocos de fundação'!L688 -> 0 | F31: ='Vigas baldrames'!H271 -> 0 | G31: m2 | H31: =E31+F31 -> 0
B32: Volume de concreto tipo 01 | D32: Concreto Fck - 30,0 MPa / Slump 9 ± 1 - Brita 1 | E32: ='Blocos de fundação'!K621+'Blocos de fundação'!K689 -> 0 | F32: ='Vigas baldrames'!I271 -> 0 | G32: m3 | H32: =E32+F32 -> 0
B33: Volume de concreto tipo 02 | D33: Concreto ... com gelo | E33: ='Blocos de fundação'!O621+'Blocos de fundação'!O689 -> 0 | G33: m3 | H33: =E33+F33 -> 0
B34: Blocos e vigas baldrames para TUBULÃO
B35: Volume de escavação | D35: Volume total a escavar | E35: ='Blocos de fundação'!N756+'Blocos de fundação'!N824 -> 0 | F35: ='Vigas baldrames'!M325 -> 0 | G35: m3 | H35: =E35+F35 -> 0
B36: Área de lastro | D36: Concreto Fck - 13,5 Mpa / Slump 6 ± 1 - Brita 1 e 2 | E36: ='Blocos de fundação'!K756+'Blocos de fundação'!K824 -> 0 | F36: ='Vigas baldrames'!G325 -> 0 | G36: m2 | H36: =E36+F36 -> 0
B37: Área de forma | D37: Material | E37: ='Blocos de fundação'!L756+'Blocos de fundação'!L824 -> 0 | F37: ='Vigas baldrames'!H325 -> 0 | G37: m2 | H37: =E37+F37 -> 0
B38: Volume de concreto tipo 01 | D38: Concreto Fck - 30,0 MPa / Slump 9 ± 1 - Brita 1 | E38: ='Blocos de fundação'!K757+'Blocos de fundação'!K825 -> 0 | F38: ='Vigas baldrames'!I325 -> 0 | G38: m3 | H38: =E38+F38 -> 0
B39: Volume de concreto tipo 02 | D39: Concreto ... com gelo | E39: ='Blocos de fundação'!O757+'Blocos de fundação'!O825 -> 0 | G39: m3 | H39: =E39+F39 -> 0
B40: Blocos e vigas baldrames para ESTACA PRÉ-MOLDADA
B41: Volume de escavação | D41: Volume total a escavar | E41: ='Blocos de fundação'!N892+'Blocos de fundação'!N960 -> 0 | F41: ='Vigas baldrames'!M379 -> 0 | G41: m3 | H41: =E41+F41 -> 0
...

Sheet Blocos de fundação
B1: Atenta-se no movimento de terra, pois o acrescimo é de 0,50m para cada lado. Porém não deve sobrepor outra área. Caso haja necessidade, ajustar a fórmula somente do movimento de terra.
B3: BLOCOS DE FUNDAÇÃO PARA ESTACA HÉLICE
C4: No ORDEM | D4: QUANT. | E4: B1 | F4: H1 | G4: B3 | H4: B2 | I4: H2 | J4: E -ALTURA DO BLOCO | K4: LASTRO | L4: AREA FORMA | M4: VOL. CONCRETO | N4: VOL. ESCAVAÇÃO | O4: TIPO DE CONCRETO
B5: SETOR A
B6: V. | K6: =G6*H6*I6 -> 0 | L6: =(H6+I6)*2*J6*G6 -> 0 | M6: =G6*H6*I6*J6 -> 0 | N6: =G6*(H6+0.5+0.5)*(I6+0.5+0.5)*J6 -> 0 | O6: 1 | P6: =((E6+(E6+H6))/2)*F6 -> 0 | Q6: =((H6+(E6+H6))/2)*I6 -> 0 | R6: =(P6+Q6)*J6 -> 0
B7: V. | K7: =G7*H7*I7 -> 0 | L7: =(H7+I7)*2*J7*G7 -> 0 | M7: =G7*H7*I7*J7 -> 0 | N7: =G7*(H7+0.5+0.5)*(I7+0.5+0.5)*J7 -> 0 | O7: 1
B8: V. | K8: =G8*H8*I8 -> 0 | L8: =(H8+I8)*2*J8*G8 -> 0 | M8: =G8*H8*I8*J8 -> 0 | N8: =G8*(H8+0.5+0.5)*(I8+0.5+0.5)*J8 -> 0 | O8: 1
B9: V. | K9: =G9*H9*I9 -> 0 | L9: =(H9+I9)*2*J9*G9 -> 0 | M9: =G9*H9*I9*J9 -> 0 | N9: =G9*(H9+0.5+0.5)*(I9+0.5+0.5)*J9 -> 0 | O9: 1
B10: V. | K10: =G10*H10*I10 -> 0 | L10: =(H10+I10)*2*J10*G10 -> 0 | M10: =G10*H10*I10*J10 -> 0 | N10: =G10*(H10+0.5+0.5)*(I10+0.5+0.5)*J10 -> 0 | O10: 1
B11: V. | K11: =G11*H11*I11 -> 0 | L11: =(H11+I11)*2*J11*G11 -> 0 | M11: =G11*H11*I11*J11 -> 0 | N11: =G11*(H11+0.5+0.5)*(I11+0.5+0.5)*J11 -> 0 | O11: 1
B12: V. | K12: =G12*H12*I12 -> 0 | L12: =(H12+I12)*2*J12*G12 -> 0 | M12: =G12*H12*I12*J12 -> 0 | N12: =G12*(H12+0.5+0.5)*(I12+0.5+0.5)*J12 -> 0 | O12: 1
B13: V. | K13: =G13*H13*I13 -> 0 | L13: =(H13+I13)*2*J13*G13 -> 0 | M13: =G13*H13*I13*J13 -> 0 | N13: =G13*(H13+0.5+0.5)*(I13+0.5+0.5)*J13 -> 0 | O13: 1
B14: V. | K14: =G14*H14*I14 -> 0 | L14: =(H14+I14)*2*J14*G14 -> 0 | M14: =G14*H14*I14*J14 -> 0 | N14: =G14*(H14+0.5+0.5)*(I14+0.5+0.5)*J14 -> 0 | O14: 1
B15: V. | K15: =G15*H15*I15 -> 0 | L15: =(H15+I15)*2*J15*G15 -> 0 | M15: =G15*H15*I15*J15 -> 0 | N15: =G15*(H15+0.5+0.5)*(I15+0.5+0.5)*J15 -> 0 | O15: 1
B16: V. | K16: =G16*H16*I16 -> 0 | L16: =(H16+I16)*2*J16*G16 -> 0 | M16: =G16*H16*I16*J16 -> 0 | N16: =G16*(H16+0.5+0.5)*(I16+0.5+0.5)*J16 -> 0 | O16: 1
B17: V. | K17: =G17*H17*I17 -> 0 | L17: =(H17+I17)*2*J17*G17 -> 0 | M17: =G17*H17*I17*J17 -> 0 | N17: =G17*(H17+0.5+0.5)*(I17+0.5+0.5)*J17 -> 0 | O17: 1
B18: V. | K18: =G18*H18*I18 -> 0 | L18: =(H18+I18)*2*J18*G18 -> 0 | M18: =G18*H18*I18*J18 -> 0 | N18: =G18*(H18+0.5+0.5)*(I18+0.5+0.5)*J18 -> 0 | O18: 1
... B25: V. | K25: =G25*H25*I25 -> 0 | L25: =(H25+I25)*2*J25*G25 -> 0 | M25: =G25*H25*I25*J25 -> 0 | N25: =G25*(H25+0.5+0.5)*(I25+0.5+0.5)*J25 -> 0 | O25: 1
B26: SETOR B
B27: V. | K27: =G27*H27*I27 -> 0 | L27: =(H27+I27)*2*J27*G27 -> 0 | M27: =G27*H27*I27*J27 -> 0 | N27: =G27*(H27+0.5+0.5)*(I27+0.5+0.5)*J27 -> 0 | O27: 1
B28: V. | K28: =G28*H28*I28 -> 0 | L28: =(H28+I28)*2*J28*G28 -> 0 | M28: =G28*H28*I28*J28 -> 0 | N28: =G28*(H28+0.5+0.5)*(I28+0.5+0.5)*J28 -> 0 | O28: 1
B29: V. | K29: =G29*H29*I29 -> 0 | L29: =(H29+I29)*2*J29*G29 -> 0 | M29: =G29*H29*I29*J29 -> 0 | N29: =G29*(H29+0.5+0.5)*(I29+0.5+0.5)*J29 -> 0 | O29: 1
B30: V. | K30: =G30*H30*I30 -> 0 | L30: =(H30+I30)*2*J30*G30 -> 0 | M30: =G30*H30*I30*J30 -> 0 | N30: =G30*(H30+0.5+0.5)*(I30+0.5+0.5)*J30 -> 0 | O30: 1
B31: V. | K31: =G31*H31*I31 -> 0 | L31: =(H31+I31)*2*J31*G31 -> 0 | M31: =G31*H31*I31*J31 -> 0 | N31: =G31*(H31+0.5+0.5)*(I31+0.5+0.5)*J31 -> 0 | O31: 1
B32: V. | K32: =G32*H32*I32 -> 0 | L32: =(H32+I32)*2*J32*G32 -> 0 | M32: =G32*H32*I32*J32 -> 0 | N32: =G32*(H32+0.5+0.5)*(I32+0.5+0.5)*J32 -> 0 | O32: 1
B33: V. | K33: =G33*H33*I33 -> 0 | L33: =(H33+I33)*2*J33*G33 -> 0 | M33: =G33*H33*I33*J33 -> 0 | N33: =G33*(H33+0.5+0.5)*(I33+0.5+0.5)*J33 -> 0 | O33: 1
B34: V. | K34: =G34*H34*I34 -> 0 | L34: =(H34+I34)*2*J34*G34 -> 0 | M34: =G34*H34*I34*J34 -> 0 | N34: =G34*(H34+0.5+0.5)*(I34+0.5+0.5)*J34 -> 0 | O34: 1
B35: V. | K35: =G35*H35*I35 -> 0 | L35: =(H35+I35)*2*J35*G35 -> 0 | M35: =G35*H35*I35*J35 -> 0 | N35: =G35*(H35+0.5+0.5)*(I35+0.5+0.5)*J35 -> 0 | O35: 1
B36: V. | K36: =G36*H36*I36 -> 0 | L36: =(H36+I36)*2*J36*G36 -> 0 | M36: =G36*H36*I36*J36 -> 0 | N36: =G36*(H36+0.5+0.5)*(I36+0.5+0.5)*J36 -> 0 | O36: 1
B37: V. | K37: =G37*H37*I37 -> 0 | L37: =(H37+I37)*2*J37*G37 -> 0 | M37: =G37*H37*I37*J37 -> 0 | N37: =G37*(H37+0.5+0.5)*(I37+0.5+0.5)*J37 -> 0 | O37: 1
B38: V. | K38: =G38*H38*I38 -> 0 | L38: =(H38+I38)*2*J38*G38 -> 0 | M38: =G38*H38*I38*J38 -> 0 | N38: =G38*(H38+0.5+0.5)*(I38+0.5+0.5)*J38 -> 0 | O38: 1
... B46: V. | K46: =G46*H46*I46 -> 0 | L46: =(H46+I46)*2*J46*G46 -> 0 | M46: =G46*H46*I46*J46 -> 0 | N46: =G46*(H46+0.5+0.5)*(I46+0.5+0.5)*J46 -> 0 | O46: 1
B47: SETOR C
B48: V. | K48: =G48*H48*I48 -> 0 | L48: =(H48+I48)*2*J48*G48 -> 0 | M48: =G48*H48*I48*J48 -> 0 | N48: =G48*(H48+0.5+0.5)*(I48+0.5+0.5)*J48 -> 0 | O48: 1
B49: V. | K49: =G49*H49*I49 -> 0 | L49: =(H49+I49)*2*J49*G49 -> 0 | M49: =G49*H49*I49*J49 -> 0 | N49: =G49*(H49+0.5+0.5)*(I49+0.5+0.5)*J49 -> 0 | O49: 1
B50: V. | K50: =G50*H50*I50 -> 0 | L50: =(H50+I50)*2*J50*G50 -> 0 | M50: =G50*H50*I50*J50 -> 0 | N50: =G50*(H50+0.5+0.5)*(I50+0.5+0.5)*J50 -> 0 | O50: 1
B51: V. | K51: =G51*H51*I51 -> 0 | L51: =(H51+I51)*2*J51*G51 -> 0 | M51: =G51*H51*I51*J51 -> 0 | N51: =G51*(H51+0.5+0.5)*(I51+0.5+0.5)*J51 -> 0 | O51: 1
B52: V. | K52: =G52*H52*I52 -> 0 | L52: =(H52+I52)*2*J52*G52 -> 0 | M52: =G52*H52*I52*J52 -> 0 | N52: =G52*(H52+0.5+0.5)*(I52+0.5+0.5)*J52 -> 0 | O52: 1
B53: V. | K53: =G53*H53*I53 -> 0 | L53: =(H53+I53)*2*J53*G53 -> 0 | M53: =G53*H53*I53*J53 -> 0 | N53: =G53*(H53+0.5+0.5)*(I53+0.5+0.5)*J53 -> 0 | O53: 1
B54: V. | K54: =G54*H54*I54 -> 0 | L54: =(H54+I54)*2*J54*G54 -> 0 | M54: =G54*H54*I54*J54 -> 0 | N54: =G54*(H54+0.5+0.5)*(I54+0.5+0.5)*J54 -> 0 | O54: 1
...

Sheet Vigas baldrames
A1: Atenta-se no movimento de terra, pois o acrescimo é de 0,50m para cada lado. Porém não deve sobrepor outra área. Caso haja necessidade, ajustar a fórmula somente do movimento de terra.
A3: VIGAS BALDRAMES PARA ESTACA HÉLICE
B4: No ORDEM | C4: QUANT. | D4: BASE DA VIGA | E4: ALT. VIGA | F4: COMPR. VIGA | G4: LASTRO | H4: AREA FORMA | I4: VOL. CONCRETO | J4: COMP. ESCAVADO | K4: LARG. ESCAVADA | L4: ALT. ESCAVADA | M4: VOL. ESCAVAÇÃO
A5: V. | G5: =C5*D5*F5 -> 0 | H5: =((E5*2*F5)+(D5*F5))*C5 -> 0 | I5: =C5*D5*E5*F5 -> 0 | M5: =J5*K5*L5 -> 0
A6: V. | G6: =C6*D6*F6 -> 0 | H6: =((E6*2*F6)+(D6*F6))*C6 -> 0 | I6: =C6*D6*E6*F6 -> 0 | M6: =J6*K6*L6 -> 0
A7: V. | G7: =C7*D7*F7 -> 0 | H7: =((E7*2*F7)+(D7*F7))*C7 -> 0 | I7: =C7*D7*E7*F7 -> 0 | M7: =J7*K7*L7 -> 0
A8: V. | G8: =C8*D8*F8 -> 0 | H8: =((E8*2*F8)+(D8*F8))*C8 -> 0 | I8: =C8*D8*E8*F8 -> 0 | M8: =J8*K8*L8 -> 0
A9: V. | G9: =C9*D9*F9 -> 0 | H9: =((E9*2*F9)+(D9*F9))*C9 -> 0 | I9: =C9*D9*E9*F9 -> 0 | M9: =J9*K9*L9 -> 0
A10: V. | G10: =C10*D10*F10 -> 0 | H10: =((E10*2*F10)+(D10*F10))*C10 -> 0 | I10: =C10*D10*E10*F10 -> 0 | M10: =J10*K10*L10 -> 0
A11: V. | G11: =C11*D11*F11 -> 0 | H11: =((E11*2*F11)+(D11*F11))*C11 -> 0 | I11: =C11*D11*E11*F11 -> 0 | M11: =J11*K11*L11 -> 0
A12: V. | G12: =C12*D12*F12 -> 0 | H12: =((E12*2*F12)+(D12*F12))*C12 -> 0 | I12: =C12*D12*E12*F12 -> 0 | M12: =J12*K12*L12 -> 0
A13: V. | G13: =C13*D13*F13 -> 0 | H13: =((E13*2*F13)+(D13*F13))*C13 -> 0 | I13: =C13*D13*E13*F13 -> 0 | M13: =J13*K13*L13 -> 0
A14: V. | G14: =C14*D14*F14 -> 0 | H14: =((E14*2*F14)+(D14*F14))*C14 -> 0 | I14: =C14*D14*E14*F14 -> 0 | M14: =J14*K14*L14 -> 0
A15: V. | G15: =C15*D15*F15 -> 0 | H15: =((E15*2*F15)+(D15*F15))*C15 -> 0 | I15: =C15*D15*E15*F15 -> 0 | M15: =J15*K15*L15 -> 0
A16: V. | G16: =C16*D16*F16 -> 0 | H16: =((E16*2*F16)+(D16*F16))*C16 -> 0 | I16: =C16*D16*E16*F16 -> 0 | M16: =J16*K16*L16 -> 0
... A54: V. | G54: =C54*D54*F54 -> 0 | H54: =((E54*2*F54)+(D54*F54))*C54 -> 0 | I54: =C54*D54*E54*F54 -> 0 | M54: =J54*K54*L54 -> 0
F55: TOTAL | G55: =SUM(G5:G54) -> 0 | H55: =SUM(H5:H54) -> 0 | I55: =SUM(I5:I54) -> 0 | M55: =SUM(M5:M54) -> 0
A57: VIGAS BALDRAMES PARA PERFIL DE FUNDAÇÃO
B58: No ORDEM | C58: QUANT. | D58: BASE DA VIGA | E58: ALT. VIGA | F58: COMPR. VIGA | G58: LASTRO | H58: AREA FORMA | I58: VOL. CONCRETO | J58: COMP. ESCAVADO | K58: LARG. ESCAVADA | L58: ALT. ESCAVADA | M58: VOL. ESCAVAÇÃO
A59: V. | G59: =C59*D59*F59 -> 0 | H59: =((E59*2*F59)+(D59*F59))*C59 -> 0 | I59: =C59*D59*E59*F59 -> 0 | M59: =J59*K59*L59 -> 0
A60: V. | G60: =C60*D60*F60 -> 0 | H60: =((E60*2*F60)+(D60*F60))*C60 -> 0 | I60: =C60*D60*E60*F60 -> 0 | M60: =J60*K60*L60 -> 0
A61: V. | G61: =C61*D61*F61 -> 0 | H61: =((E61*2*F61)+(D61*F61))*C61 -> 0 | I61: =C61*D61*E61*F61 -> 0 | M61: =J61*K61*L61 -> 0
A62: V. | G62: =C62*D62*F62 -> 0 | H62: =((E62*2*F62)+(D62*F62))*C62 -> 0 | I62: =C62*D62*E62*F62 -> 0 | M62: =J62*K62*L62 -> 0
A63: V. | G63: =C63*D63*F63 -> 0 | H63: =((E63*2*F63)+(D63*F63))*C63 -> 0 | I63: =C63*D63*E63*F63 -> 0 | M63: =J63*K63*L63 -> 0
A64: V. | G64: =C64*D64*F64 -> 0 | H64: =((E64*2*F64)+(D64*F64))*C64 -> 0 | I64: =C64*D64*E64*F64 -> 0 | M64: =J64*K64*L64 -> 0
A65: V. | G65: =C65*D65*F65 -> 0 | H65: =((E65*2*F65)+(D65*F65))*C65 -> 0 | I65: =C65*D65*E65*F65 -> 0 | M65: =J65*K65*L65 -> 0
A66: V. | G66: =C66*D66*F66 -> 0 | H66: =((E66*2*F66)+(D66*F66))*C66 -> 0 | I66: =C66*D66*E66*F66 -> 0 | M66: =J66*K66*L66 -> 0
A67: V. | G67: =C67*D67*F67 -> 0 | H67: =((E67*2*F67)+(D67*F67))*C67 -> 0 | I67: =C67*D67*E67*F67 -> 0 | M67: =J67*K67*L67 -> 0
A68: V. | G68: =C68*D68*F68 -> 0 | H68: =((E68*2*F68)+(D68*F68))*C68 -> 0 | I68: =C68*D68*E68*F68 -> 0 | M68: =J68*K68*L68 -> 0
A69: V. | G69: =C69*D69*F69 -> 0 | H69: =((E69*2*F69)+(D69*F69))*C69 -> 0 | I69: =C69*D69*E69*F69 -> 0 | M69: =J69*K69*L69 -> 0
A70: V. | G70: =C70*D70*F70 -> 0 | H70: =((E70*2*F70)+(D70*F70))*C70 -> 0 | I70: =C70*D70*E70*F70 -> 0 | M70: =J70*K70*L70 -> 0
... A108: V. | G108: =C108*D108*F108 -> 0 | H108: =((E108*2*F108)+(D108*F108))*C108 -> 0 | I108: =C108*D108*E108*F108 -> 0 | M108: =J108*K108*L108 -> 0
F109: TOTAL | G109: =SUM(G59:G108) -> 0 | H109: =SUM(H59:H108) -> 0 | I109: =SUM(I59:I108) -> 0 | M109: =SUM(M59:M108) -> 0
A111: VIGAS BALDRAMES PARA ESTACA STRAUSS
B112: No ORDEM | C112: QUANT. | D112: BASE DA VIGA | E112: ALT. VIGA | F112: COMPR. VIGA | G112: LASTRO | H112: AREA FORMA | I112: VOL. CONCRETO | J112: COMP. ESCAVADO | K112: LARG. ESCAVADA | L112: ALT. ESCAVADA | M112: VOL. ESCAVAÇÃO
A113: V. | G113: =C113*D113*F113 -> 0 | H113: =((E113*2*F113)+(D113*F113))*C113 -> 0 | I113: =C113*D113*E113*F113 -> 0 | M113: =J113*K113*L113 -> 0
A114: V. | G114: =C114*D114*F114 -> 0 | H114: =((E114*2*F114)+(D114*F114))*C114 -> 0 | I114: =C114*D114*E114*F114 -> 0 | M114: =J114*K114*L114 -> 0
A115: V. | G115: =C115*D115*F115 -> 0 | H115: =((E115*2*F115)+(D115*F115))*C115 -> 0 | I115: =C115*D115*E115*F115 -> 0 | M115: =J115*K115*L115 -> 0
A116: V. | G116: =C116*D116*F116 -> 0 | H116: =((E116*2*F116)+(D116*F116))*C116 -> 0 | I116: =C116*D116*E116*F116 -> 0 | M116: =J116*K116*L116 -> 0
A117: V. | G117: =C117*D117*F117 -> 0 | H117: =((E117*2*F117)+(D117*F117))*C117 -> 0 | I117: =C117*D117*E117*F117 -> 0 | M117: =J117*K117*L117 -> 0
...

Sheet Cortinas
B2: Atenta-se no movimento de terra, pois o acrescimo é de 0,50m para cada lado. Porém não deve sobrepor outra área. Caso haja necessidade, ajustar a fórmula somente do movimento de terra.
B3: LEVANTAMENTO DE CORTINA
C6: No ORDEM | D6: QUANT. | E6: BASE | F6: ALTURA | G6: COMPR. | H6: LASTRO | I6: AREA FORMA | J6: VOL. CONCRETO | K6: VOL. ESCAVAÇÃO
B7: V. | H7: =D7*E7*G7 -> 0 | I7: =((F7*2*G7)+(E7*G7))*D7 -> 0 | J7: =D7*E7*F7*G7 -> 0 | K7: =D7*(E7+0.5+0.5)*F7*(G7+0.5+0.5) -> 0
B8: V. | H8: =D8*E8*G8 -> 0 | I8: =((F8*2*G8)+(E8*G8))*D8 -> 0 | J8: =D8*E8*F8*G8 -> 0 | K8: =D8*(E8+0.5+0.5)*F8*(G8+0.5+0.5) -> 0
B9: V. | H9: =D9*E9*G9 -> 0 | I9: =((F9*2*G9)+(E9*G9))*D9 -> 0 | J9: =D9*E9*F9*G9 -> 0 | K9: =D9*(E9+0.5+0.5)*F9*(G9+0.5+0.5) -> 0
B10: V. | H10: =D10*E10*G10 -> 0 | I10: =((F10*2*G10)+(E10*G10))*D10 -> 0 | J10: =D10*E10*F10*G10 -> 0 | K10: =D10*(E10+0.5+0.5)*F10*(G10+0.5+0.5) -> 0
B11: V. | H11: =D11*E11*G11 -> 0 | I11: =((F11*2*G11)+(E11*G11))*D11 -> 0 | J11: =D11*E11*F11*G11 -> 0 | K11: =D11*(E11+0.5+0.5)*F11*(G11+0.5+0.5) -> 0
B12: V. | H12: =D12*E12*G12 -> 0 | I12: =((F12*2*G12)+(E12*G12))*D12 -> 0 | J12: =D12*E12*F12*G12 -> 0 | K12: =D12*(E12+0.5+0.5)*F12*(G12+0.5+0.5) -> 0
B13: V. | H13: =D13*E13*G13 -> 0 | I13: =((F13*2*G13)+(E13*G13))*D13 -> 0 | J13: =D13*E13*F13*G13 -> 0 | K13: =D13*(E13+0.5+0.5)*F13*(G13+0.5+0.5) -> 0
B14: V. | H14: =D14*E14*G14 -> 0 | I14: =((F14*2*G14)+(E14*G14))*D14 -> 0 | J14: =D14*E14*F14*G14 -> 0 | K14: =D14*(E14+0.5+0.5)*F14*(G14+0.5+0.5) -> 0
B15: V. | H15: =D15*E15*G15 -> 0 | I15: =((F15*2*G15)+(E15*G15))*D15 -> 0 | J15: =D15*E15*F15*G15 -> 0 | K15: =D15*(E15+0.5+0.5)*F15*(G15+0.5+0.5) -> 0
B16: V. | H16: =D16*E16*G16 -> 0 | I16: =((F16*2*G16)+(E16*G16))*D16 -> 0 | J16: =D16*E16*F16*G16 -> 0 | K16: =D16*(E16+0.5+0.5)*F16*(G16+0.5+0.5) -> 0
B17: V. | H17: =D17*E17*G17 -> 0 | I17: =((F17*2*G17)+(E17*G17))*D17 -> 0 | J17: =D17*E17*F17*G17 -> 0 | K17: =D17*(E17+0.5+0.5)*F17*(G17+0.5+0.5) -> 0
B18: V. | H18: =D18*E18*G18 -> 0 | I18: =((F18*2*G18)+(E18*G18))*D18 -> 0 | J18: =D18*E18*F18*G18 -> 0 | K18: =D18*(E18+0.5+0.5)*F18*(G18+0.5+0.5) -> 0
... B56: V. | H56: =D56*E56*G56 -> 0 | I56: =((F56*2*G56)+(E56*G56))*D56 -> 0 | J56: =D56*E56*F56*G56 -> 0 | K56: =D56*(E56+0.5+0.5)*F56*(G56+0.5+0.5) -> 0
G57: TOTAL | H57: =SUM(H7:H56) -> 0 | I57: =SUM(I7:I56) -> 0 | J57: =SUM(J7:J56) -> 0 | K57: =SUM(K7:K56) -> 0

Sheet Escada
B2: MEMORIA DE CALCULO PARA ESCADA - CONCRETO E FORMA
C3: 3° SS | H3: 2° SS | M3: 1° SS | R3: Térreo | W3: 1° Pav | AB3: 2° Pav | AG3: 3° Pav | AL3: 4° Pav | AQ3: Tipo Studios | AV3: Tipo Residencial | BA3: Lazer | BF3: Duplex Inferior | BK3: Duplex Superior | BP3: Casa de máquinas | BU3: Cobertura | BZ3: INTERNA
B5: DEGRAU | C5: D1 | D5: D2 | E5: D3 | F5: D4 | G5: TOTAL | H5: D1 | I5: D2 | J5: D3 | K5: D4 | L5: TOTAL | M5: D1 | N5: D2 | O5: D3 | P5: D4 | Q5: TOTAL | R5: D1 | S5: D2 | T5: D3 | U5: D4 | V5: TOTAL | W5: D1 | X5: D2 | Y5: D3 | Z5: D4 | AA5: TOTAL | AB5: D1 | AC5: D2 | AD5: D3 | AE5: D4 | AF5: TOTAL | AG5: D1 | AH5: D2 | AI5: D3 | AJ5: D4 | AK5: TOTAL | AL5: D1 | AM5: D2 | AN5: D3 | AO5: D4 | AP5: TOTAL | AQ5: D1 | AR5: D2 | AS5: D3 | AT5: D4 | AU5: TOTAL | AV5: D1 | AW5: D2 | AX5: D3 | AY5: D4 | AZ5: TOTAL | BA5: D1 | BB5: D2 | BC5: D3 | BD5: D4 | BE5: TOTAL | BF5: D1 | BG5: D2 | BH5: D3 | BI5: D4 | BJ5: TOTAL | BK5: D1 | BL5: D2 | BM5: D3 | BN5: D4 | BO5: TOTAL | BP5: D1 | BQ5: D2 | BR5: D3 | BS5: D4 | BT5: TOTAL | BU5: D1 | BV5: D2 | BW5: D3 | BX5: D4 | BY5: TOTAL | BZ5: D1 | CA5: D2 | CB5: D3 | CC5: TOTAL | CD5: D1 | CE5: D2 | CF5: D3 | CG5: D4
B6: No. DEGRAU | BA6: 0 | BB6: 0 | BC6: 0 | BD6: 0 | BF6: 0 | BG6: 0 | BH6: 0 | BI6: 0 | BK6: 0 | BL6: 0 | BM6: 0 | BN6: 0 | BP6: 0 | BQ6: 0 | BR6: 0 | BS6: 0 | BU6: 0 | BV6: 0 | BW6: 0 | BX6: 0 | BZ6: 0 | CA6: 0 | CB6: 0
B7: COMPR. | C7: 1.23 | D7: 1.36 | E7: 1.36 | F7: 1.36 | H7: 1.3 | I7: 1.3 | J7: 1.3 | K7: 1.36 | M7: 1.36 | N7: 1.36 | O7: 1.36 | P7: 1.36 | R7: 1.36 | S7: 1.36 | T7: 1.36 | U7: 1.36 | W7: 1.36 | X7: 1.36 | Y7: 1.36 | Z7: 1.36 | AB7: 1.36 | AC7: 1.36 | AD7: 1.36 | AE7: 1.36 | AG7: 1.36 | AH7: 1.36 | AI7: 1.36 | AJ7: 1.36 | AL7: 1.36 | AM7: 1.36 | AN7: 1.36 | AO7: 1.36 | AQ7: 1.36 | AR7: 1.36 | AS7: 1.36 | AT7: 1.36 | AV7: 1.36 | AW7: 1.36 | AX7: 1.36 | AY7: 1.36 | BA7: 1.36 | BB7: 1.36 | BC7: 1.36 | BD7: 1.36 | BF7: 1.36 | BG7: 1.36 | BH7: 1.36 | BI7: 1.36 | BK7: 1.36 | BL7: 1.36 | BM7: 1.36 | BN7: 1.36 | BP7: 1.36 | BQ7: 1.36 | BR7: 1.36 | BS7: 1.36 | BU7: 1.36 | BV7: 1.36 | BW7: 1.36 | BX7: 1.36 | BZ7: 1.36 | CA7: 1.36 | CB7: 1.36
B8: LARGURA | C8: 0.26 | D8: 0.28 | E8: 0.28 | F8: 0.28 | H8: 0.28 | I8: 0.3 | J8: 0.28 | K8: 0.28 | M8: 0.28 | N8: 0.28 | O8: 0.28 | P8: 0.28 | R8: 0.28 | S8: 0.28 | T8: 0.28 | U8: 0.28 | W8: 0.28 | X8: 0.28 | Y8: 0.28 | Z8: 0.28 | AB8: 0.28 | AC8: 0.28 | AD8: 0.28 | AE8: 0.28 | AG8: 0.28 | AH8: 0.28 | AI8: 0.28 | AJ8: 0.28 | AL8: 0.28 | AM8: 0.28 | AN8: 0.28 | AO8: 0.28 | AQ8: 0.28 | AR8: 0.28 | AS8: 0.28 | AT8: 0.28 | AV8: 0.28 | AW8: 0.28 | AX8: 0.28 | AY8: 0.28 | BA8: 0.28 | BB8: 0.28 | BC8: 0.28 | BD8: 0.28 | BF8: 0.28 | BG8: 0.28 | BH8: 0.28 | BI8: 0.28 | BK8: 0.28 | BL8: 0.28 | BM8: 0.28 | BN8: 0.28 | BP8: 0.28 | BQ8: 0.28 | BR8: 0.28 | BS8: 0.28 | BU8: 0.28 | BV8: 0.28 | BW8: 0.28 | BX8: 0.28 | BZ8: 0.28 | CA8: 0.28 | CB8: 0.28
B9: ESPELHO | C9: 0.19 | D9: 0.18 | E9: 0.18 | F9: 0.18 | H9: 0.18 | I9: 0.18 | J9: 0.18 | K9: 0.18 | M9: 0.18 | N9: 0.18 | O9: 0.18 | P9: 0.18 | R9: 0.18 | S9: 0.18 | T9: 0.18 | U9: 0.18 | W9: 0.18 | X9: 0.18 | Y9: 0.18 | Z9: 0.18 | AB9: 0.18 | AC9: 0.18 | AD9: 0.18 | AE9: 0.18 | AG9: 0.18 | AH9: 0.18 | AI9: 0.18 | AJ9: 0.18 | AL9: 0.18 | AM9: 0.18 | AN9: 0.18 | AO9: 0.18 | AQ9: 0.18 | AR9: 0.18 | AS9: 0.18 | AT9: 0.18 | AV9: 0.18 | AW9: 0.18 | AX9: 0.18 | AY9: 0.18 | BA9: 0.18 | BB9: 0.18 | BC9: 0.18 | BD9: 0.18 | BF9: 0.18 | BG9: 0.18 | BH9: 0.18 | BI9: 0.18 | BK9: 0.18 | BL9: 0.18 | BM9: 0.18 | BN9: 0.18 | BP9: 0.18 | BQ9: 0.18 | BR9: 0.18 | BS9: 0.18 | BU9: 0.18 | BV9: 0.18 | BW9: 0.18 | BX9: 0.18 | BZ9: 0.18 | CA9: 0.18 | CB9: 0.18
B10: VOL. PARCIAL (m3) | C10: =C7*C8*C9*C6 -> 0 | D10: =D7*D8*D9*D6 -> 0 | E10: =E7*E8*E9*E6 -> 0 | F10: =F7*F8*F9*F6 -> 0 | H10: =H7*H8*H9*H6 -> 0 | I10: =I7*I8*I9*I6 -> 0 | J10: =J7*J8*J9*J6 -> 0 | K10: =K7*K8*K9*K6 -> 0 | M10: =M7*M8*M9*M6 -> 0 | N10: =N7*N8*N9*N6 -> 0 | O10: =O7*O8*O9*O6 -> 0 | P10: =P7*P8*P9*P6 -> 0 | R10: =R7*R8*R9*R6 -> 0 | S10: =S7*S8*S9*S6 -> 0 | T10: =T7*T8*T9*T6 -> 0 | U10: =U7*U8*U9*U6 -> 0 | W10: =W7*W8*W9*W6 -> 0 | X10: =X7*X8*X9*X6 -> 0 | Y10: =Y7*Y8*Y9*Y6 -> 0 | Z10: =Z7*Z8*Z9*Z6 -> 0 | AB10: =AB7*AB8*AB9*AB6 -> 0 | AC10: =AC7*AC8*AC9*AC6 -> 0 | AD10: =AD7*AD8*AD9*AD6 -> 0 | AE10: =AE7*AE8*AE9*AE6 -> 0 | AG10: =AG7*AG8*AG9*AG6 -> 0 | AH10: =AH7*AH8*AH9*AH6 -> 0 | AI10: =AI7*AI8*AI9*AI6 -> 0 | AJ10: =AJ7*AJ8*AJ9*AJ6 -> 0 | AL10: =AL7*AL8*AL9*AL6 -> 0 | AM10: =AM7*AM8*AM9*AM6 -> 0 | AN10: =AN7*AN8*AN9*AN6 -> 0 | AO10: =AO7*AO8*AO9*AO6 -> 0 | AQ10: =AQ7*AQ8*AQ9*AQ6 -> 0 | AR10: =AR7*AR8*AR9*AR6 -> 0 | AS10: =AS7*AS8*AS9*AS6 -> 0 | AT10: =AT7*AT8*AT9*AT6 -> 0 | AV10: =AV7*AV8*AV9*AV6 -> 0 | AW10: =AW7*AW8*AW9*AW6 -> 0 | AX10: =AX7*AX8*AX9*AX6 -> 0 | AY10: =AY7*AY8*AY9*AY6 -> 0 | BA10: =BA7*BA8*BA9*BA6 -> 0 | BB10: =BB7*BB8*BB9*BB6 -> 0 | BC10: =BC7*BC8*BC9*BC6 -> 0 | BD10: =BD7*BD8*BD9*BD6 -> 0 | BF10: =BF7*BF8*BF9*BF6 -> 0 | BG10: =BG7*BG8*BG9*BG6 -> 0 | BH10: =BH7*BH8*BH9*BH6 -> 0 | BI10: =BI7*BI8*BI9*BI6 -> 0 | BK10: =BK7*BK8*BK9*BK6 -> 0 | BL10: =BL7*BL8*BL9*BL6 -> 0 | BM10: =BM7*BM8*BM9*BM6 -> 0 | BN10: =BN7*BN8*BN9*BN6 -> 0 | BP10: =BP7*BP8*BP9*BP6 -> 0 | BQ10: =BQ7*BQ8*BQ9*BQ6 -> 0 | BR10: =BR7*BR8*BR9*BR6 -> 0 | BS10: =BS7*BS8*BS9*BS6 -> 0 | BU10: =BU7*BU8*BU9*BU6 -> 0 | BV10: =BV7*BV8*BV9*BV6 -> 0 | BW10: =BW7*BW8*BW9*BW6 -> 0 | BX10: =BX7*BX8*BX9*BX6 -> 0 | BZ10: =BZ7*BZ8*BZ9*BZ6 -> 0 | CA10: =CA7*CA8*CA9*CA6 -> 0 | CB10: =CB7*CB8*CB9*CB6 -> 0 | CD10: =CD7*CD8*CD9*CD6 -> 0 | CE10: =CE7*CE8*CE9*CE6 -> 0 | CF10: =CF7*CF8*CF9*CF6 -> 0 | CG10: =CG7*CG8*CG9*CG6 -> 0
B11: VOL. REAL (m3) | C11: =C10/2 -> 0 | D11: =D10/2 -> 0 | E11: =E10/2 -> 0 | F11: =F10/2 -> 0 | G11: =SUM(C11:F11) -> 0 | H11: =H10/2 -> 0 | I11: =I10/2 -> 0 | J11: =J10/2 -> 0 | K11: =K10/2 -> 0 | L11: =SUM(H11:K11) -> 0 | M11: =M10/2 -> 0 | N11: =N10/2 -> 0 | O11: =O10/2 -> 0 | P11: =P10/2 -> 0 | Q11: =SUM(M11:P11) -> 0 | R11: =R10/2 -> 0 | S11: =S10/2 -> 0 | T11: =T10/2 -> 0 | U11: =U10/2 -> 0 | V11: =SUM(R11:U11) -> 0 | W11: =W10/2 -> 0 | X11: =X10/2 -> 0 | Y11: =Y10/2 -> 0 | Z11: =Z10/2 -> 0 | AA11: =SUM(W11:Z11) -> 0 | AB11: =AB10/2 -> 0 | AC11: =AC10/2 -> 0 | AD11: =AD10/2 -> 0 | AE11: =AE10/2 -> 0 | AF11: =SUM(AB11:AE11) -> 0 | AG11: =AG10/2 -> 0 | AH11: =AH10/2 -> 0 | AI11: =AI10/2 -> 0 | AJ11: =AJ10/2 -> 0 | AK11: =SUM(AG11:AJ11) -> 0 | AL11: =AL10/2 -> 0 | AM11: =AM10/2 -> 0 | AN11: =AN10/2 -> 0 | AO11: =AO10/2 -> 0 | AP11: =SUM(AL11:AO11) -> 0 | AQ11: =AQ10/2 -> 0 | AR11: =AR10/2 -> 0 | AS11: =AS10/2 -> 0 | AT11: =AT10/2 -> 0 | AU11: =SUM(AQ11:AT11) -> 0 | AV11: =AV10/2 -> 0 | AW11: =AW10/2 -> 0 | AX11: =AX10/2 -> 0 | AY11: =AY10/2 -> 0 | AZ11: =SUM(AV11:AY11) -> 0 | BA11: =BA10/2 -> 0 | BB11: =BB10/2 -> 0 | BC11: =BC10/2 -> 0 | BD11: =BD10/2 -> 0 | BE11: =SUM(BA11:BD11) -> 0 | BF11: =BF10/2 -> 0 | BG11: =BG10/2 -> 0 | BH11: =BH10/2 -> 0 | BI11: =BI10/2 -> 0 | BJ11: =SUM(BF11:BI11) -> 0 | BK11: =BK10/2 -> 0 | BL11: =BL10/2 -> 0 | BM11: =BM10/2 -> 0 | BN11: =BN10/2 -> 0 | BO11: =SUM(BK11:BN11) -> 0 | BP11: =BP10/2 -> 0 | BQ11: =BQ10/2 -> 0 | BR11: =BR10/2 -> 0 | BS11: =BS10/2 -> 0 | BT11: =SUM(BP11:BS11) -> 0 | BU11: =BU10/2 -> 0 | BV11: =BV10/2 -> 0 | BW11: =BW10/2 -> 0 | BX11: =BX10/2 -> 0 | BY11: =SUM(BU11:BX11) -> 0 | BZ11: =BZ10/2 -> 0 | CA11: =CA10/2 -> 0 | CB11: =CB10/2 -> 0 | CC11: =SUM(BZ11:CB11) -> 0 | CD11: =CD10/2 -> 0 | CE11: =CE10/2 -> 0 | CF11: =CF10/2 -> 0 | CG11: =CG10/2 -> 0
B12: ÁREA REAL (m2) | C12: =C7*C9*C6 -> 0 | D12: =D7*D9*D6 -> 0 | E12: =E7*E9*E6 -> 0 | F12: =F7*F9*F6 -> 0 | G12: =SUM(C12:F12) -> 0 | H12: =H7*H9*H6 -> 0 | I12: =I7*I9*I6 -> 0 | J12: =J7*J9*J6 -> 0 | K12: =K7*K9*K6 -> 0 | L12: =SUM(H12:K12) -> 0 | M12: =M7*M9*M6 -> 0 | N12: =N7*N9*N6 -> 0 | O12: =O7*O9*O6 -> 0 | P12: =P7*P9*P6 -> 0 | Q12: =SUM(M12:P12) -> 0 | R12: =R7*R9*R6 -> 0 | S12: =S7*S9*S6 -> 0 | T12: =T7*T9*T6 -> 0 | U12: =U7*U9*U6 -> 0 | V12: =SUM(R12:U12) -> 0 | W12: =W7*W9*W6 -> 0 | X12: =X7*X9*X6 -> 0 | Y12: =Y7*Y9*Y6 -> 0 | Z12: =Z7*Z9*Z6 -> 0 | AA12: =SUM(W12:Z12) -> 0 | AB12: =AB7*AB9*AB6 -> 0 | AC12: =AC7*AC9*AC6 -> 0 | AD12: =AD7*AD9*AD6 -> 0 | AE12: =AE7*AE9*AE6 -> 0 | AF12: =SUM(AB12:AE12) -> 0 | AG12: =AG7*AG9*AG6 -> 0 | AH12: =AH7*AH9*AH6 -> 0 | AI12: =AI7*AI9*AI6 -> 0 | AJ12: =AJ7*AJ9*AJ6 -> 0 | AK12: =SUM(AG12:AJ12) -> 0 | AL12: =AL7*AL9*AL6 -> 0 | AM12: =AM7*AM9*AM6 -> 0 | AN12: =AN7*AN9*AN6 -> 0 | AO12: =AO7*AO9*AO6 -> 0 | AP12: =SUM(AL12:AO12) -> 0 | AQ12: =AQ7*AQ9*AQ6 -> 0 | AR12: =AR7*AR9*AR6 -> 0 | AS12: =AS7*AS9*AS6 -> 0 | AT12: =AT7*AT9*AT6 -> 0 | AU12: =SUM(AQ12:AT12) -> 0 | AV12: =AV7*AV9*AV6 -> 0 | AW12: =AW7*AW9*AW6 -> 0 | AX12: =AX7*AX9*AX6 -> 0 | AY12: =AY7*AY9*AY6 -> 0 | AZ12: =SUM(AV12:AY12) -> 0 | BA12: =BA7*BA9*BA6 -> 0 | BB12: =BB7*BB9*BB6 -> 0 | BC12: =BC7*BC9*BC6 -> 0 | BD12: =BD7*BD9*BD6 -> 0 | BE12: =SUM(BA12:BD12) -> 0 | BF12: =BF7*BF9*BF6 -> 0 | BG12: =BG7*BG9*BG6 -> 0 | BH12: =BH7*BH9*BH6 -> 0 | BI12: =BI7*BI9*BI6 -> 0 | BJ12: =SUM(BF12:BI12) -> 0 | BK12: =BK7*BK9*BK6 -> 0 | BL12: =BL7*BL9*BL6 -> 0 | BM12: =BM7*BM9*BM6 -> 0 | BN12: =BN7*BN9*BN6 -> 0 | BO12: =SUM(BK12:BN12) -> 0 | BP12: =BP7*BP9*BP6 -> 0 | BQ12: =BQ7*BQ9*BQ6 -> 0 | BR12: =BR7*BR9*BR6 -> 0 | BS12: =BS7*BS9*BS6 -> 0 | BT12: =SUM(BP12:BS12) -> 0 | BU12: =BU7*BU9*BU6 -> 0 | BV12: =BV7*BV9*BV6 -> 0 | BW12: =BW7*BW9*BW6 -> 0 | BX12: =BX7*BX9*BX6 -> 0 | BY12: =SUM(BU12:BX12) -> 0 | BZ12: =BZ7*BZ9*BZ6 -> 0 | CA12: =CA7*CA9*CA6 -> 0 | CB12: =CB7*CB9*CB6 -> 0 | CC12: =SUM(BZ12:CB12) -> 0 | CD12: =CD7*CD9*CD6 -> 0 | CE12: =CE7*CE9*CE6 -> 0 | CF12: =CF7*CF9*CF6 -> 0 | CG12: =CG7*CG9*CG6 -> 0
B13: LAJE DE APOIO | C13: L.A.1 | D13: L.A.2 | E13: L.A.3 | F13: L.A.4 | G13: TOTAL | H13: L.A.1 | I13: L.A.2 | J13: L.A.3 | K13: L.A.4 | L13: TOTAL | M13: L.A.1 | N13: L.A.2 | O13: L.A.3 | P13: L.A.4 | Q13: TOTAL | R13: L.A.1 | S13: L.A.2 | T13: L.A.3 | U13: L.A.4 | V13: TOTAL | W13: L.A.1 | X13: L.A.2 | Y13: L.A.3 | Z13: L.A.4 | AA13: TOTAL | AB13: L.A.1 | AC13: L.A.2 | AD13: L.A.3 | AE13: L.A.4 | AF13: TOTAL | AG13: L.A.1 | AH13: L.A.2 | AI13: L.A.3 | AJ13: L.A.4 | AK13: TOTAL | AL13: L.A.1 | AM13: L.A.2 | AN13: L.A.3 | AO13: L.A.4 | AP13: TOTAL | AQ13: L.A.1 | AR13: L.A.2 | AS13: L.A.3 | AT13: L.A.4 | AU13: TOTAL | AV13: L.A.1 | AW13: L.A.2 | AX13: L.A.3 | AY13: L.A.4 | AZ13: TOTAL | BA13: L.A.1 | BB13: L.A.2 | BC13: L.A.3 | BD13: L.A.4 | BE13: TOTAL | BF13: L.A.1 | BG13: L.A.2 | BH13: L.A.3 | BI13: L.A.4 | BJ13: TOTAL | BK13: L.A.1 | BL13: L.A.2 | BM13: L.A.3 | BN13: L.A.4 | BO13: TOTAL | BP13: L.A.1 | BQ13: L.A.2 | BR13: L.A.3 | BS13: L.A.4 | BT13: TOTAL | BU13: L.A.1 | BV13: L.A.2 | BW13: L.A.3 | BX13: L.A.4 | BY13: TOTAL | BZ13: L.A.1 | CA13: L.A.2 | CB13: L.A.3 | CC13: TOTAL | CD13: L.A.1 | CE13: L.A.2 | CF13: L.A.3 | CG13: L.A.4
B14: QUANT. (q) | K14: 0 | M14: 0 | N14: 0 | O14: 0 | P14: 0 | R14: 0 | S14: 0 | T14: 0 | U14: 0 | W14: 0 | X14: 0 | Y14: 0 | Z14: 0 | AB14: 0 | AC14: 0 | AD14: 0 | AE14: 0 | AG14: 0 | AH14: 0 | AI14: 0 | AJ14: 0 | AL14: 0 | AM14: 0 | AN14: 0 | AO14: 0 | AQ14: 0 | AR14: 0 | AS14: 0 | AT14: 0 | AV14: 0 | AW14: 0 | AX14: 0 | AY14: 0 | BA14: 0 | BB14: 0 | BC14: 0 | BD14: 0 | BF14: 0 | BG14: 0 | BH14: 0 | BI14: 0 | BK14: 0 | BL14: 0 | BM14: 0 | BN14: 0 | BP14: 0 | BQ14: 0 | BR14: 0 | BS14: 0 | BU14: 0 | BV14: 0 | BW14: 0 | BX14: 0 | BZ14: 0 | CA14: 0 | CB14: 0
B15: ALTURA (a) | C15: 3.6 | D15: 1.8 | E15: 1.8 | F15: 1.8 | H15: 0.57 | I15: 1.98 | J15: 0.56 | K15: 1.8 | M15: 1.8 | N15: 1.8 | O15: 1.8 | P15: 1.8 | R15: 1.8 | S15: 1.8 | T15: 1.8 | U15: 1.8 | W15: 1.8 | X15: 1.8 | Y15: 1.8 | Z15: 1.8 | AB15: 1.8 | AC15: 1.8 | AD15: 1.8 | AE15: 1.8 | AG15: 1.8 | AH15: 1.8 | AI15: 1.8 | AJ15: 1.8 | AL15: 1.8 | AM15: 1.8 | AN15: 1.8 | AO15: 1.8 | AQ15: 1.8 | AR15: 1.8 | AS15: 1.8 | AT15: 1.8 | AV15: 1.8 | AW15: 1.8 | AX15: 1.8 | AY15: 1.8 | BA15: 1.8 | BB15: 1.8 | BC15: 1.8 | BD15: 1.8 | BF15: 1.8 | BG15: 1.8 | BH15: 1.8 | BI15: 1.8 | BK15: 1.8 | BL15: 1.8 | BM15: 1.8 | BN15: 1.8 | BP15: 1.8 | BQ15: 1.8 | BR15: 1.8 | BS15: 1.8 | BU15: 1.8 | BV15: 1.8 | BW15: 1.8 | BX15: 1.8 | BZ15: 1.8 | CA15: 1.8 | CB15: 1.8
B16: PROJEÇÃO (b) | C16: 4.69 | D16: 2.95 | E16: 2.95 | F16: 2.95 | H16: 0.88 | I16: 3.08 | J16: 2.95 | K16: 2.95 | M16: 2.95 | N16: 2.95 | O16: 2.95 | P16: 2.95 | R16: 2.95 | S16: 2.95 | T16: 2.95 | U16: 2.95 | W16: 2.95 | X16: 2.95 | Y16: 2.95 | Z16: 2.95 | AB16: 2.95 | AC16: 2.95 | AD16: 2.95 | AE16: 2.95 | AG16: 2.95 | AH16: 2.95 | AI16: 2.95 | AJ16: 2.95 | AL16: 2.95 | AM16: 2.95 | AN16: 2.95 | AO16: 2.95 | AQ16: 2.95 | AR16: 2.95 | AS16: 2.95 | AT16: 2.95 | AV16: 2.95 | AW16: 2.95 | AX16: 2.95 | AY16: 2.95 | BA16: 2.95 | BB16: 2.95 | BC16: 2.95 | BD16: 2.95 | BF16: 2.95 | BG16: 2.95 | BH16: 2.95 | BI16: 2.95 | BK16: 2.95 | BL16: 2.95 | BM16: 2.95 | BN16: 2.95 | BP16: 2.95 | BQ16: 2.95 | BR16: 2.95 | BS16: 2.95 | BU16: 2.95 | BV16: 2.95 | BW16: 2.95 | BX16: 2.95 | BZ16: 2.95 | CA16: 2.95 | CB16: 2.95
B17: COMPR. (c) | C17: =SQRT(C15^2+C16^2) -> 5.9123684 | D17: =SQRT(D15^2+D16^2) -> 3.4557922 | E17: =SQRT(E15^2+E16^2) -> 3.4557922 | F17: =SQRT(F15^2+F16^2) -> 3.4557922 | H17: =SQRT(H15^2+H16^2) -> 1.0484751 | I17: =SQRT(I15^2+I16^2) -> 3.6615297 | J17: =SQRT(J15^2+J16^2) -> 3.0026821 | K17: =SQRT(K15^2+K16^2) -> 3.4557922 | M17: =SQRT(M15^2+M16^2) -> 3.4557922 | N17: =SQRT(N15^2+N16^2) -> 3.4557922 | O17: =SQRT(O15^2+O16^2) -> 3.4557922 | P17: =SQRT(P15^2+P16^2) -> 3.4557922 | R17: =SQRT(R15^2+R16^2) -> 3.4557922 | S17: =SQRT(S15^2+S16^2) -> 3.4557922 | T17: =SQRT(T15^2+T16^2) -> 3.4557922 | U17: =SQRT(U15^2+U16^2) -> 3.4557922 | W17: =SQRT(W15^2+W16^2) -> 3.4557922 | X17: =SQRT(X15^2+X16^2) -> 3.4557922 | Y17: =SQRT(Y15^2+Y16^2) -> 3.4557922 | Z17: =SQRT(Z15^2+Z16^2) -> 3.4557922 | AB17: =SQRT(AB15^2+AB16^2) -> 3.4557922 | AC17: =SQRT(AC15^2+AC16^2) -> 3.4557922 | AD17: =SQRT(AD15^2+AD16^2) -> 3.4557922 | AE17: =SQRT(AE15^2+AE16^2) -> 3.4557922 | AG17: =SQRT(AG15^2+AG16^2) -> 3.4557922 | AH17: =SQRT(AH15^2+AH16^2) -> 3.4557922 | AI17: =SQRT(AI15^2+AI16^2) -> 3.4557922 | AJ17: =SQRT(AJ15^2+AJ16^2) -> 3.4557922 | AL17: =SQRT(AL15^2+AL16^2) -> 3.4557922 | AM17: =SQRT(AM15^2+AM16^2) -> 3.4557922 | AN17: =SQRT(AN15^2+AN16^2) -> 3.4557922 | AO17: =SQRT(AO15^2+AO16^2) -> 3.4557922 | AQ17: =SQRT(AQ15^2+AQ16^2) -> 3.4557922 | AR17: =SQRT(AR15^2+AR16^2) -> 3.4557922 | AS17: =SQRT(AS15^2+AS16^2) -> 3.4557922 | AT17: =SQRT(AT15^2+AT16^2) -> 3.4557922 | AV17: =SQRT(AV15^2+AV16^2) -> 3.4557922 | AW17: =SQRT(AW15^2+AW16^2) -> 3.4557922 | AX17: =SQRT(AX15^2+AX16^2) -> 3.4557922 | AY17: =SQRT(AY15^2+AY16^2) -> 3.4557922 | BA17: =SQRT(BA15^2+BA16^2) -> 3.4557922 | BB17: =SQRT(BB15^2+BB16^2) -> 3.4557922 | BC17: =SQRT(BC15^2+BC16^2) -> 3.4557922 | BD17: =SQRT(BD15^2+BD16^2) -> 3.4557922 | BF17: =SQRT(BF15^2+BF16^2) -> 3.4557922 | BG17: =SQRT(BG15^2+BG16^2) -> 3.4557922 | BH17: =SQRT(BH15^2+BH16^2) -> 3.4557922 | BI17: =SQRT(BI15^2+BI16^2) -> 3.4557922 | BK17: =SQRT(BK15^2+BK16^2) -> 3.4557922 | BL17: =SQRT(BL15^2+BL16^2) -> 3.4557922 | BM17: =SQRT(BM15^2+BM16^2) -> 3.4557922 | BN17: =SQRT(BN15^2+BN16^2) -> 3.4557922 | BP17: =SQRT(BP15^2+BP16^2) -> 3.4557922 | BQ17: =SQRT(BQ15^2+BQ16^2) -> 3.4557922 | BR17: =SQRT(BR15^2+BR16^2) -> 3.4557922 | BS17: =SQRT(BS15^2+BS16^2) -> 3.4557922 | BU17: =SQRT(BU15^2+BU16^2) -> 3.4557922 | BV17: =SQRT(BV15^2+BV16^2) -> 3.4557922 | BW17: =SQRT(BW15^2+BW16^2) -> 3.4557922 | BX17: =SQRT(BX15^2+BX16^2) -> 3.4557922 | BZ17: =SQRT(BZ15^2+BZ16^2) -> 3.4557922 | CA17: =SQRT(CA15^2+CA16^2) -> 3.4557922 | CB17: =SQRT(CB15^2+CB16^2) -> 3.4557922 | CD17: =SQRT(CD15^2+CD16^2) -> 0 | CE17: =SQRT(CE15^2+CE16^2) -> 0 | CF17: =SQRT(CF15^2+CF16^2) -> 0 | CG17: =SQRT(CG15^2+CG16^2) -> 0
B18: LARGURA (d) | C18: 1.23 | D18: 1.21 | E18: 1.21 | F18: 1.21 | H18: 1.3 | I18: 1.3 | J18: 1.3 | K18: 1.21 | M18: 1.21 | N18: 1.21 | O18: 1.21 | P18: 1.21 | R18: 1.21 | S18: 1.21 | T18: 1.21 | U18: 1.21 | W18: 1.21 | X18: 1.21 | Y18: 1.21 | Z18: 1.21 | AB18: 1.21 | AC18: 1.21 | AD18: 1.21 | AE18: 1.21 | AG18: 1.21 | AH18: 1.21 | AI18: 1.21 | AJ18: 1.21 | AL18: 1.21 | AM18: 1.21 | AN18: 1.21 | AO18: 1.21 | AQ18: 1.21 | AR18: 1.21 | AS18: 1.21 | AT18: 1.21 | AV18: 1.21 | AW18: 1.21 | AX18: 1.21 | AY18: 1.21 | BA18: 1.21 | BB18: 1.21 | BC18: 1.21 | BD18: 1.21 | BF18: 1.21 | BG18: 1.21 | BH18: 1.21 | BI18: 1.21 | BK18: 1.21 | BL18: 1.21 | BM18: 1.21 | BN18: 1.21 | BP18: 1.21 | BQ18: 1.21 | BR18: 1.21 | BS18: 1.21 | BU18: 1.21 | BV18: 1.21 | BW18: 1.21 | BX18: 1.21 | BZ18: 1.21 | CA18: 1.21 | CB18: 1.21
B19: ESPESSURA (e) | C19: 0.17 | D19: 0.1 | E19: 0.1 | F19: 0.1 | H19: 0.14 | I19: 0.14 | J19: 0.14 | K19: 0.1 | M19: 0.1 | N19: 0.1 | O19: 0.1 | P19: 0.1 | R19: 0.1 | S19: 0.1 | T19: 0.1 | U19: 0.1 | W19: 0.1 | X19: 0.1 | Y19: 0.1 | Z19: 0.1 | AB19: 0.1 | AC19: 0.1 | AD19: 0.1 | AE19: 0.1 | AG19: 0.1 | AH19: 0.1 | AI19: 0.1 | AJ19: 0.1 | AL19: 0.1 | AM19: 0.1 | AN19: 0.1 | AO19: 0.1 | AQ19: 0.1 | AR19: 0.1 | AS19: 0.1 | AT19: 0.1 | AV19: 0.1 | AW19: 0.1 | AX19: 0.1 | AY19: 0.1 | BA19: 0.1 | BB19: 0.1 | BC19: 0.1 | BD19: 0.1 | BF19: 0.1 | BG19: 0.1 | BH19: 0.1 | BI19: 0.1 | BK19: 0.1 | BL19: 0.1 | BM19: 0.1 | BN19: 0.1 | BP19: 0.1 | BQ19: 0.1 | BR19: 0.1 | BS19: 0.1 | BU19: 0.1 | BV19: 0.1 | BW19: 0.1 | BX19: 0.1 | BZ19: 0.1 | CA19: 0.1 | CB19: 0.1
B20: VOL.REAL (c x d x e x q) (m3) | C20: =C17*C18*C19*C14 -> 0 | D20: =D17*D18*D19*D14 -> 0 | E20: =E17*E18*E19*E14 -> 0 | F20: =F17*F18*F19*F14 -> 0 | G20: =SUM(C20:F20) -> 0 | H20: =H17*H18*H19*H14 -> 0 | I20: =I17*I18*I19*I14 -> 0 | J20: =J17*J18*J19*J14 -> 0 | K20: =K17*K18*K19*K14 -> 0 | L20: =SUM(H20:K20) -> 0 | M20: =M17*M18*M19*M14 -> 0 | N20: =N17*N18*N19*N14 -> 0 | O20: =O17*O18*O19*O14 -> 0 | P20: =P17*P18*P19*P14 -> 0 | Q20: =SUM(M20:P20) -> 0 | R20: =R17*R18*R19*R14 -> 0 | S20: =S17*S18*S19*S14 -> 0 | T20: =T17*T18*T19*T14 -> 0 | U20: =U17*U18*U19*U14 -> 0 | V20: =SUM(R20:U20) -> 0 | W20: =W17*W18*W19*W14 -> 0 | X20: =X17*X18*X19*X14 -> 0 | Y20: =Y17*Y18*Y19*Y14 -> 0 | Z20: =Z17*Z18*Z19*Z14 -> 0 | AA20: =SUM(W20:Z20) -> 0 | AB20: =AB17*AB18*AB19*AB14 -> 0 | AC20: =AC17*AC18*AC19*AC14 -> 0 | AD20: =AD17*AD18*AD19*AD14 -> 0 | AE20: =AE17*AE18*AE19*AE14 -> 0 | AF20: =SUM(AB20:AE20) -> 0 | AG20: =AG17*AG18*AG19*AG14 -> 0 | AH20: =AH17*AH18*AH19*AH14 -> 0 | AI20: =AI17*AI18*AI19*AI14 -> 0 | AJ20: =AJ17*AJ18*AJ19*AJ14 -> 0 | AK20: =SUM(AG20:AJ20) -> 0 | AL20: =AL17*AL18*AL19*AL14 -> 0 | AM20: =AM17*AM18*AM19*AM14 -> 0 | AN20: =AN17*AN18*AN19*AN14 -> 0 | AO20: =AO17*AO18*AO19*AO14 -> 0 | AP20: =SUM(AL20:AO20) -> 0 | AQ20: =AQ17*AQ18*AQ19*AQ14 -> 0 | AR20: =AR17*AR18*AR19*AR14 -> 0 | AS20: =AS17*AS18*AS19*AS14 -> 0 | AT20: =AT17*AT18*AT19*AT14 -> 0 | AU20: =SUM(AQ20:AT20) -> 0 | AV20: =AV17*AV18*AV19*AV14 -> 0 | AW20: =AW17*AW18*AW19*AW14 -> 0 | AX20: =AX17*AX18*AX19*AX14 -> 0 | AY20: =AY17*AY18*AY19*AY14 -> 0 | AZ20: =SUM(AV20:AY20) -> 0 | BA20: =BA17*BA18*BA19*BA14 -> 0 | BB20: =BB17*BB18*BB19*BB14 -> 0 | BC20: =BC17*BC18*BC19*BC14 -> 0 | BD20: =BD17*BD18*BD19*BD14 -> 0 | BE20: =SUM(BA20:BD20) -> 0 | BF20: =BF17*BF18*BF19*BF14 -> 0 | BG20: =BG17*BG18*BG19*BG14 -> 0 | BH20: =BH17*BH18*BH19*BH14 -> 0 | BI20: =BI17*BI18*BI19*BI14 -> 0 | BJ20: =SUM(BF20:BI20) -> 0 | BK20: =BK17*BK18*BK19*BK14 -> 0 | BL20: =BL17*BL18*BL19*BL14 -> 0 | BM20: =BM17*BM18*BM19*BM14 -> 0 | BN20: =BN17*BN18*BN19*BN14 -> 0 | BO20: =SUM(BK20:BN20) -> 0 | BP20: =BP17*BP18*BP19*BP14 -> 0 | BQ20: =BQ17*BQ18*BQ19*BQ14 -> 0 | BR20: =BR17*BR18*BR19*BR14 -> 0 | BS20: =BS17*BS18*BS19*BS14 -> 0 | BT20: =SUM(BP20:BS20) -> 0 | BU20: =BU17*BU18*BU19*BU14 -> 0 | BV20: =BV17*BV18*BV19*BV14 -> 0 | BW20: =BW17*BW18*BW19*BW14 -> 0 | BX20: =BX17*BX18*BX19*BX14 -> 0 | BY20: =SUM(BU20:BX20) -> 0 | BZ20: =BZ17*BZ18*BZ19*BZ14 -> 0 | CA20: =CA17*CA18*CA19*CA14 -> 0 | CB20: =CB17*CB18*CB19*CB14 -> 0 | CC20: =SUM(BZ20:CB20) -> 0 | CD20: =CD17*CD18*CD19*CD14 -> 0 | CE20: =CE17*CE18*CE19*CE14 -> 0 | CF20: =CF17*CF18*CF19*CF14 -> 0 | CG20: =CG17*CG18*CG19*CG14 -> 0
B21: ÁREA REAL (m2) | C21: =C17*C18*C14 -> 0 | D21: =D17*D18*D14 -> 0 | E21: =E17*E18*E14 -> 0 | F21: =F17*F18*F14 -> 0 | G21: =SUM(C21:F21) -> 0 | H21: =H17*H18*H14 -> 0 | I21: =I17*I18*I14 -> 0 | J21: =J17*J18*J14 -> 0 | K21: =K17*K18*K14 -> 0 | L21: =SUM(H21:K21) -> 0 | M21: =M17*M18*M14 -> 0 | N21: =N17*N18*N14 -> 0 | O21: =O17*O18*O14 -> 0 | P21: =P17*P18*P14 -> 0 | Q21: =SUM(M21:P21) -> 0 | R21: =R17*R18*R14 -> 0 | S21: =S17*S18*S14 -> 0 | T21: =T17*T18*T14 -> 0 | U21: =U17*U18*U14 -> 0 | V21: =SUM(R21:U21) -> 0 | W21: =W17*W18*W14 -> 0 | X21: =X17*X18*X14 -> 0 | Y21: =Y17*Y18*Y14 -> 0 | Z21: =Z17*Z18*Z14 -> 0 | AA21: =SUM(W21:Z21) -> 0 | AB21: =AB17*AB18*AB14 -> 0 | AC21: =AC17*AC18*AC14 -> 0 | AD21: =AD17*AD18*AD14 -> 0 | AE21: =AE17*AE18*AE14 -> 0 | AF21: =SUM(AB21:AE21) -> 0 | AG21: =AG17*AG18*AG14 -> 0 | AH21: =AH17*AH18*AH14 -> 0 | AI21: =AI17*AI18*AI14 -> 0 | AJ21: =AJ17*AJ18*AJ14 -> 0 | AK21: =SUM(AG21:AJ21) -> 0 | AL21: =AL17*AL18*AL14 -> 0 | AM21: =AM17*AM18*AM14 -> 0 | AN21: =AN17*AN18*AN14 -> 0 | AO21: =AO17*AO18*AO14 -> 0 | AP21: =SUM(AL21:AO21) -> 0 | AQ21: =AQ17*AQ18*AQ14 -> 0 | AR21: =AR17*AR18*AR14 -> 0 | AS21: =AS17*AS18*AS14 -> 0 | AT21: =AT17*AT18*AT14 -> 0 | AU21: =SUM(AQ21:AT21) -> 0 | AV21: =AV17*AV18*AV14 -> 0 | AW21: =AW17*AW18*AW14 -> 0 | AX21: =AX17*AX18*AX14 -> 0 | AY21: =AY17*AY18*AY14 -> 0 | AZ21: =SUM(AV21:AY21) -> 0 | BA21: =BA17*BA18*BA14 -> 0 | BB21: =BB17*BB18*BB14 -> 0 | BC21: =BC17*BC18*BC14 -> 0 | BD21: =BD17*BD18*BD14 -> 0 | BE21: =SUM(BA21:BD21) -> 0 | BF21: =BF17*BF18*BF14 -> 0 | BG21: =BG17*BG18*BG14 -> 0 | BH21: =BH17*BH18*BH14 -> 0 | BI21: =BI17*BI18*BI14 -> 0 | BJ21: =SUM(BF21:BI21) -> 0 | BK21: =BK17*BK18*BK14 -> 0 | BL21: =BL17*BL18*BL14 -> 0 | BM21: =BM17*BM18*BM14 -> 0 | BN21: =BN17*BN18*BN14 -> 0 | BO21: =SUM(BK21:BN21) -> 0 | BP21: =BP17*BP18*BP14 -> 0 | BQ21: =BQ17*BQ18*BQ14 -> 0 | BR21: =BR17*BR18*BR14 -> 0 | BS21: =BS17*BS18*BS14 -> 0 | BT21: =SUM(BP21:BS21) -> 0 | BU21: =BU17*BU18*BU14 -> 0 | BV21: =BV17*BV18*BV14 -> 0 | BW21: =BW17*BW18*BW14 -> 0 | BX21: =BX17*BX18*BX14 -> 0 | BY21: =SUM(BU21:BX21) -> 0 | BZ21: =BZ17*BZ18*BZ14 -> 0 | CA21: =CA17*CA18*CA14 -> 0 | CB21: =CB17*CB18*CB14 -> 0 | CC21: =SUM(BZ21:CB21) -> 0 | CD21: =CD17*CD18*CD14 -> 0 | CE21: =CE17*CE18*CE14 -> 0 | CF21: =CF17*CF18*CF14 -> 0 | CG21: =CG17*CG18*CG14 -> 0
B22: PATAMAR | C22: PAT.1 | D22: PAT.2 | E22: PAT.3 | F22: PAT.4 | G22: TOTAL | H22: PAT.1 | I22: PAT.2 | J22: PAT.3 | K22: PAT.4 | L22: TOTAL | M22: PAT.1 | N22: PAT.2 | O22: PAT.3 | P22: PAT.4 | Q22: TOTAL | R22: PAT.1 | S22: PAT.2 | T22: PAT.3 | U22: PAT.4 | V22: TOTAL | W22: PAT.1 | X22: PAT.2 | Y22: PAT.3 | Z22: PAT.4 | AA22: TOTAL | AB22: PAT.1 | AC22: PAT.2 | AD22: PAT.3 | AE22: PAT.4 | AF22: TOTAL | AG22: PAT.1 | AH22: PAT.2 | AI22: PAT.3 | AJ22: PAT.4 | AK22: TOTAL | AL22: PAT.1 | AM22: PAT.2 | AN22: PAT.3 | AO22: PAT.4 | AP22: TOTAL | AQ22: PAT.1 | AR22: PAT.2 | AS22: PAT.3 | AT22: PAT.4 | AU22: TOTAL | AV22: PAT.1 | AW22: PAT.2 | AX22: PAT.3 | AY22: PAT.4 | AZ22: TOTAL | BA22: PAT.1 | BB22: PAT.2 | BC22: PAT.3 | BD22: PAT.4 | BE22: TOTAL | BF22: PAT.1 | BG22: PAT.2 | BH22: PAT.3 | BI22: PAT.4 | BJ22: TOTAL | BK22: PAT.1 | BL22: PAT.2 | BM22: PAT.3 | BN22: PAT.4 | BO22: TOTAL | BP22: PAT.1 | BQ22: PAT.2 | BR22: PAT.3 | BS22: PAT.4 | BT22: TOTAL | BU22: PAT.1 | BV22: PAT.2 | BW22: PAT.3 | BX22: PAT.4 | BY22: TOTAL | BZ22: PAT.1 | CA22: PAT.2 | CB22: PAT.3 | CC22: TOTAL | CD22: PAT.1 | CE22: PAT.2 | CF22: PAT.3 | CG22: PAT.4
B23: QUANT. (q) | R23: 0 | S23: 0 | T23: 0 | U23: 0 | W23: 0 | X23: 0 | Y23: 0 | Z23: 0 | AB23: 0 | AC23: 0 | AD23: 0 | AE23: 0 | AG23: 0 | AH23: 0 | AI23: 0 | AJ23: 0 | AL23: 0 | AM23: 0 | AN23: 0 | AO23: 0 | AQ23: 0 | AR23: 0 | AS23: 0 | AT23: 0 | AV23: 0 | AW23: 0 | AX23: 0 | AY23: 0 | BA23: 0 | BB23: 0 | BC23: 0 | BD23: 0 | BF23: 0 | BG23: 0 | BH23: 0 | BI23: 0 | BK23: 0 | BL23: 0 | BM23: 0 | BN23: 0 | BP23: 0 | BQ23: 0 | BR23: 0 | BS23: 0 | BU23: 0 | BV23: 0 | BW23: 0 | BX23: 0 | BZ23: 0 | CA23: 0 | CB23: 0
B24: COMPR. | C24: 1.02 | D24: 4.04 | E24: 2.56 | F24: 2.56 | H24: 0.99 | I24: 0.96 | J24: 1.3 | K24: 2.56 | M24: 2.56 | N24: 2.56 | O24: 2.56 | P24: 2.56 | R24: 2.56 | S24: 2.56 | T24: 2.56 | U24: 2.56 | W24: 2.56 | X24: 2.56 | Y24: 2.56 | Z24: 2.56 | AB24: 2.56 | AC24: 2.56 | AD24: 2.56 | AE24: 2.56 | AG24: 2.56 | AH24: 2.56 | AI24: 2.56 | AJ24: 2.56 | AL24: 2.56 | AM24: 2.56 | AN24: 2.56 | AO24: 2.56 | AQ24: 2.56 | AR24: 2.56 | AS24: 2.56 | AT24: 2.56 | AV24: 2.56 | AW24: 2.56 | AX24: 2.56 | AY24: 2.56 | BA24: 2.56 | BB24: 2.56 | BC24: 2.56 | BD24: 2.56 | BF24: 2.56 | BG24: 2.56 | BH24: 2.56 | BI24: 2.56 | BK24: 2.56 | BL24: 2.56 | BM24: 2.56 | BN24: 2.56 | BP24: 2.56 | BQ24: 2.56 | BR24: 2.56 | BS24: 2.56 | BU24: 2.56 | BV24: 2.56 | BW24: 2.56 | BX24: 2.56 | BZ24: 2.56 | CA24: 2.56 | CB24: 2.56
B25: LARGURA | C25: 1.23 | D25: 1.23 | E25: 1.2 | F25: 1.2 | H25: 1.3 | I25: 1.3 | J25: 5.39 | K25: 1.2 | M25: 1.2 | N25: 1.2 | O25: 1.2 | P25: 1.2 | R25: 1.2 | S25: 1.2 | T25: 1.2 | U25: 1.2 | W25: 1.2 | X25: 1.2 | Y25: 1.2 | Z25: 1.2 | AB25: 1.2 | AC25: 1.2 | AD25: 1.2 | AE25: 1.2 | AG25: 1.2 | AH25: 1.2 | AI25: 1.2 | AJ25: 1.2 | AL25: 1.2 | AM25: 1.2 | AN25: 1.2 | AO25: 1.2 | AQ25: 1.2 | AR25: 1.2 | AS25: 1.2 | AT25: 1.2 | AV25: 1.2 | AW25: 1.2 | AX25: 1.2 | AY25: 1.2 | BA25: 1.2 | BB25: 1.2 | BC25: 1.2 | BD25: 1.2 | BF25: 1.2 | BG25: 1.2 | BH25: 1.2 | BI25: 1.2 | BK25: 1.2 | BL25: 1.2 | BM25: 1.2 | BN25: 1.2 | BP25: 1.2 | BQ25: 1.2 | BR25: 1.2 | BS25: 1.2 | BU25: 1.2 | BV25: 1.2 | BW25: 1.2 | BX25: 1.2 | BZ25: 1.2 | CA25: 1.2 | CB25: 1.2
B26: ESPESSURA | C26: 0.12 | D26: 0.12 | E26: 0.1 | F26: 0.1 | H26: 0.12 | I26: 0.12 | J26: 0.12 | K26: 0.1 | M26: 0.1 | N26: 0.1 | O26: 0.1 | P26: 0.1 | R26: 0.1 | S26: 0.1 | T26: 0.1 | U26: 0.1 | W26: 0.1 | X26: 0.1 | Y26: 0.1 | Z26: 0.1 | AB26: 0.1 | AC26: 0.1 | AD26: 0.1 | AE26: 0.1 | AG26: 0.1 | AH26: 0.1 | AI26: 0.1 | AJ26: 0.1 | AL26: 0.1 | AM26: 0.1 | AN26: 0.1 | AO26: 0.1 | AQ26: 0.1 | AR26: 0.1 | AS26: 0.1 | AT26: 0.1 | AV26: 0.1 | AW26: 0.1 | AX26: 0.1 | AY26: 0.1 | BA26: 0.1 | BB26: 0.1 | BC26: 0.1 | BD26: 0.1 | BF26: 0.1 | BG26: 0.1 | BH26: 0.1 | BI26: 0.1 | BK26: 0.1 | BL26: 0.1 | BM26: 0.1 | BN26: 0.1 | BP26: 0.1 | BQ26: 0.1 | BR26: 0.1 | BS26: 0.1 | BU26: 0.1 | BV26: 0.1 | BW26: 0.1 | BX26: 0.1 | BZ26: 0.1 | CA26: 0.1 | CB26: 0.1
B27: VOL. REAL (m3) | C27: =C24*C25*C26*C23 -> 0 | D27: =D24*D25*D26*D23 -> 0 | E27: =E24*E25*E26*E23 -> 0 | F27: =F24*F25*F26*F23 -> 0 | G27: =SUM(C27:F27) -> 0 | H27: =H24*H25*H26*H23 -> 0 | I27: =I24*I25*I26*I23 -> 0 | J27: =J24*J25*J26*J23 -> 0 | K27: =K24*K25*K26*K23 -> 0 | L27: =SUM(H27:K27) -> 0 | M27: =M24*M25*M26*M23 -> 0 | N27: =N24*N25*N26*N23 -> 0 | O27: =O24*O25*O26*O23 -> 0 | P27: =P24*P25*P26*P23 -> 0 | Q27: =SUM(M27:P27) -> 0 | R27: =R24*R25*R26*R23 -> 0 | S27: =S24*S25*S26*S23 -> 0 | T27: =T24*T25*T26*T23 -> 0 | U27: =U24*U25*U26*U23 -> 0 | V27: =SUM(R27:U27) -> 0 | W27: =W24*W25*W26*W23 -> 0 | X27: =X24*X25*X26*X23 -> 0 | Y27: =Y24*Y25*Y26*Y23 -> 0 | Z27: =Z24*Z25*Z26*Z23 -> 0 | AA27: =SUM(W27:Z27) -> 0 | AB27: =AB24*AB25*AB26*AB23 -> 0 | AC27: =AC24*AC25*AC26*AC23 -> 0 | AD27: =AD24*AD25*AD26*AD23 -> 0 | AE27: =AE24*AE25*AE26*AE23 -> 0 | AF27: =SUM(AB27:AE27) -> 0 | AG27: =AG24*AG25*AG26*AG23 -> 0 | AH27: =AH24*AH25*AH26*AH23 -> 0 | AI27: =AI24*AI25*AI26*AI23 -> 0 | AJ27: =AJ24*AJ25*AJ26*AJ23 -> 0 | AK27: =SUM(AG27:AJ27) -> 0 | AL27: =AL24*AL25*AL26*AL23 -> 0 | AM27: =AM24*AM25*AM26*AM23 -> 0 | AN27: =AN24*AN25*AN26*AN23 -> 0 | AO27: =AO24*AO25*AO26*AO23 -> 0 | AP27: =SUM(AL27:AO27) -> 0 | AQ27: =AQ24*AQ25*AQ26*AQ23 -> 0 | AR27: =AR24*AR25*AR26*AR23 -> 0 | AS27: =AS24*AS25*AS26*AS23 -> 0 | AT27: =AT24*AT25*AT26*AT23 -> 0 | AU27: =SUM(AQ27:AT27) -> 0 | AV27: =AV24*AV25*AV26*AV23 -> 0 | AW27: =AW24*AW25*AW26*AW23 -> 0 | AX27: =AX24*AX25*AX26*AX23 -> 0 | AY27: =AY24*AY25*AY26*AY23 -> 0 | AZ27: =SUM(AV27:AY27) -> 0 | BA27: =BA24*BA25*BA26*BA23 -> 0 | BB27: =BB24*BB25*BB26*BB23 -> 0 | BC27: =BC24*BC25*BC26*BC23 -> 0 | BD27: =BD24*BD25*BD26*BD23 -> 0 | BE27: =SUM(BA27:BD27) -> 0 | BF27: =BF24*BF25*BF26*BF23 -> 0 | BG27: =BG24*BG25*BG26*BG23 -> 0 | BH27: =BH24*BH25*BH26*BH23 -> 0 | BI27: =BI24*BI25*BI26*BI23 -> 0 | BJ27: =SUM(BF27:BI27) -> 0 | BK27: =BK24*BK25*BK26*BK23 -> 0 | BL27: =BL24*BL25*BL26*BL23 -> 0 | BM27: =BM24*BM25*BM26*BM23 -> 0 | BN27: =BN24*BN25*BN26*BN23 -> 0 | BO27: =SUM(BK27:BN27) -> 0 | BP27: =BP24*BP25*BP26*BP23 -> 0 | BQ27: =BQ24*BQ25*BQ26*BQ23 -> 0 | BR27: =BR24*BR25*BR26*BR23 -> 0 | BS27: =BS24*BS25*BS26*BS23 -> 0 | BT27: =SUM(BP27:BS27) -> 0 | BU27: =BU24*BU25*BU26*BU23 -> 0 | BV27: =BV24*BV25*BV26*BV23 -> 0 | BW27: =BW24*BW25*BW26*BW23 -> 0 | BX27: =BX24*BX25*BX26*BX23 -> 0 | BY27: =SUM(BU27:BX27) -> 0 | BZ27: =BZ24*BZ25*BZ26*BZ23 -> 0 | CA27: =CA24*CA25*CA26*CA23 -> 0 | CB27: =CB24*CB25*CB26*CB23 -> 0 | CC27: =SUM(BZ27:CB27) -> 0 | CD27: =CD24*CD25*CD26*CD23 -> 0 | CE27: =CE24*CE25*CE26*CE23 -> 0 | CF27: =CF24*CF25*CF26*CF23 -> 0 | CG27: =CG24*CG25*CG26*CG23 -> 0
